
Running tests...
----------------------------------------------------------------------
EEEEEEEEEEEEEEEEEFFFFFFFFFFFFFFFFFFFFFFFFFFFFFFFFFFFFFFFFFFFFFFFFFFF..EEEE...E....EEsEEE
======================================================================
ERROR [0.042s]: test_get_vaccine_date_no_ok (test_get_vaccine_date_tests.TestGetVaccineDate)
# long 32 in patient system id , not valid
----------------------------------------------------------------------
Traceback (most recent call last):
  File "C:\Users\ALEJANDRA\AppData\Local\Programs\Python\Python38\lib\unittest\case.py", line 60, in testPartExecutor
    yield
  File "C:\Users\ALEJANDRA\AppData\Local\Programs\Python\Python38\lib\unittest\case.py", line 676, in run
    self._callTestMethod(testMethod)
  File "C:\Users\ALEJANDRA\AppData\Local\Programs\Python\Python38\lib\unittest\case.py", line 633, in _callTestMethod
    method()
  File "c:\users\alejandra\desktop\uni\segundo\software_devel\g89.2022.t01.fp\target\venv\build\cpython-3.8.0.final.0\lib\site-packages\freezegun\api.py", line 789, in wrapper
    result = func(*args, **kwargs)
  File "c:\users\alejandra\desktop\uni\segundo\software_devel\g89.2022.t01.fp\src\unittest\python\test_get_vaccine_date_tests.py", line 114, in test_get_vaccine_date_no_ok
    my_manager.get_vaccine_date(file_test, DATE)
TypeError: get_vaccine_date() takes 2 positional arguments but 3 were given

======================================================================
ERROR [0.019s]: test_get_vaccine_date_no_ok_data_manipulated (test_get_vaccine_date_tests.TestGetVaccineDate)
no quotes , not valid
----------------------------------------------------------------------
Traceback (most recent call last):
  File "C:\Users\ALEJANDRA\AppData\Local\Programs\Python\Python38\lib\unittest\case.py", line 60, in testPartExecutor
    yield
  File "C:\Users\ALEJANDRA\AppData\Local\Programs\Python\Python38\lib\unittest\case.py", line 676, in run
    self._callTestMethod(testMethod)
  File "C:\Users\ALEJANDRA\AppData\Local\Programs\Python\Python38\lib\unittest\case.py", line 633, in _callTestMethod
    method()
  File "c:\users\alejandra\desktop\uni\segundo\software_devel\g89.2022.t01.fp\target\venv\build\cpython-3.8.0.final.0\lib\site-packages\freezegun\api.py", line 789, in wrapper
    result = func(*args, **kwargs)
  File "c:\users\alejandra\desktop\uni\segundo\software_devel\g89.2022.t01.fp\src\unittest\python\test_get_vaccine_date_tests.py", line 153, in test_get_vaccine_date_no_ok_data_manipulated
    shutil.copy(JSON_FILES_RF2_PATH + "store_patient_manipulated.json",
  File "C:\Users\ALEJANDRA\AppData\Local\Programs\Python\Python38\lib\shutil.py", line 409, in copy
    copyfile(src, dst, follow_symlinks=follow_symlinks)
  File "C:\Users\ALEJANDRA\AppData\Local\Programs\Python\Python38\lib\shutil.py", line 259, in copyfile
    with open(src, 'rb') as fsrc, open(dst, 'wb') as fdst:
FileNotFoundError: [Errno 2] No such file or directory: 'C:\\Users\\ALEJANDRADesktop/uni/segundo/software_devel/G89.2022.T01.FP/src/JsonFiles/RF2/store_patient_manipulated.json'

======================================================================
ERROR [0.005s]: test_get_vaccine_date_no_ok_invalid_format_dash (test_get_vaccine_date_tests.TestGetVaccineDate)
Test the get vaccine date method with an invalid format
----------------------------------------------------------------------
Traceback (most recent call last):
  File "C:\Users\ALEJANDRA\AppData\Local\Programs\Python\Python38\lib\unittest\case.py", line 60, in testPartExecutor
    yield
  File "C:\Users\ALEJANDRA\AppData\Local\Programs\Python\Python38\lib\unittest\case.py", line 676, in run
    self._callTestMethod(testMethod)
  File "C:\Users\ALEJANDRA\AppData\Local\Programs\Python\Python38\lib\unittest\case.py", line 633, in _callTestMethod
    method()
  File "c:\users\alejandra\desktop\uni\segundo\software_devel\g89.2022.t01.fp\target\venv\build\cpython-3.8.0.final.0\lib\site-packages\freezegun\api.py", line 789, in wrapper
    result = func(*args, **kwargs)
  File "c:\users\alejandra\desktop\uni\segundo\software_devel\g89.2022.t01.fp\src\unittest\python\test_get_vaccine_date_tests.py", line 271, in test_get_vaccine_date_no_ok_invalid_format_dash
    my_manager.get_vaccine_date(file_test, date_invalid)
TypeError: get_vaccine_date() takes 2 positional arguments but 3 were given

======================================================================
ERROR [0.004s]: test_get_vaccine_date_no_ok_invalid_format_days_0 (test_get_vaccine_date_tests.TestGetVaccineDate)
Test the get vaccine date method with an invalid format
----------------------------------------------------------------------
Traceback (most recent call last):
  File "C:\Users\ALEJANDRA\AppData\Local\Programs\Python\Python38\lib\unittest\case.py", line 60, in testPartExecutor
    yield
  File "C:\Users\ALEJANDRA\AppData\Local\Programs\Python\Python38\lib\unittest\case.py", line 676, in run
    self._callTestMethod(testMethod)
  File "C:\Users\ALEJANDRA\AppData\Local\Programs\Python\Python38\lib\unittest\case.py", line 633, in _callTestMethod
    method()
  File "c:\users\alejandra\desktop\uni\segundo\software_devel\g89.2022.t01.fp\target\venv\build\cpython-3.8.0.final.0\lib\site-packages\freezegun\api.py", line 789, in wrapper
    result = func(*args, **kwargs)
  File "c:\users\alejandra\desktop\uni\segundo\software_devel\g89.2022.t01.fp\src\unittest\python\test_get_vaccine_date_tests.py", line 359, in test_get_vaccine_date_no_ok_invalid_format_days_0
    my_manager.get_vaccine_date(file_test, date_invalid)
TypeError: get_vaccine_date() takes 2 positional arguments but 3 were given

======================================================================
ERROR [0.004s]: test_get_vaccine_date_no_ok_invalid_format_days_exceed (test_get_vaccine_date_tests.TestGetVaccineDate)
Test the get vaccine date method with an invalid format
----------------------------------------------------------------------
Traceback (most recent call last):
  File "C:\Users\ALEJANDRA\AppData\Local\Programs\Python\Python38\lib\unittest\case.py", line 60, in testPartExecutor
    yield
  File "C:\Users\ALEJANDRA\AppData\Local\Programs\Python\Python38\lib\unittest\case.py", line 676, in run
    self._callTestMethod(testMethod)
  File "C:\Users\ALEJANDRA\AppData\Local\Programs\Python\Python38\lib\unittest\case.py", line 633, in _callTestMethod
    method()
  File "c:\users\alejandra\desktop\uni\segundo\software_devel\g89.2022.t01.fp\target\venv\build\cpython-3.8.0.final.0\lib\site-packages\freezegun\api.py", line 789, in wrapper
    result = func(*args, **kwargs)
  File "c:\users\alejandra\desktop\uni\segundo\software_devel\g89.2022.t01.fp\src\unittest\python\test_get_vaccine_date_tests.py", line 337, in test_get_vaccine_date_no_ok_invalid_format_days_exceed
    my_manager.get_vaccine_date(file_test, date_invalid)
TypeError: get_vaccine_date() takes 2 positional arguments but 3 were given

======================================================================
ERROR [0.004s]: test_get_vaccine_date_no_ok_invalid_format_month_0 (test_get_vaccine_date_tests.TestGetVaccineDate)
Test the get vaccine date method with an invalid format
----------------------------------------------------------------------
Traceback (most recent call last):
  File "C:\Users\ALEJANDRA\AppData\Local\Programs\Python\Python38\lib\unittest\case.py", line 60, in testPartExecutor
    yield
  File "C:\Users\ALEJANDRA\AppData\Local\Programs\Python\Python38\lib\unittest\case.py", line 676, in run
    self._callTestMethod(testMethod)
  File "C:\Users\ALEJANDRA\AppData\Local\Programs\Python\Python38\lib\unittest\case.py", line 633, in _callTestMethod
    method()
  File "c:\users\alejandra\desktop\uni\segundo\software_devel\g89.2022.t01.fp\target\venv\build\cpython-3.8.0.final.0\lib\site-packages\freezegun\api.py", line 789, in wrapper
    result = func(*args, **kwargs)
  File "c:\users\alejandra\desktop\uni\segundo\software_devel\g89.2022.t01.fp\src\unittest\python\test_get_vaccine_date_tests.py", line 315, in test_get_vaccine_date_no_ok_invalid_format_month_0
    my_manager.get_vaccine_date(file_test, date_invalid)
TypeError: get_vaccine_date() takes 2 positional arguments but 3 were given

======================================================================
ERROR [0.005s]: test_get_vaccine_date_no_ok_invalid_format_month_exceed (test_get_vaccine_date_tests.TestGetVaccineDate)
Test the get vaccine date method with an invalid format
----------------------------------------------------------------------
Traceback (most recent call last):
  File "C:\Users\ALEJANDRA\AppData\Local\Programs\Python\Python38\lib\unittest\case.py", line 60, in testPartExecutor
    yield
  File "C:\Users\ALEJANDRA\AppData\Local\Programs\Python\Python38\lib\unittest\case.py", line 676, in run
    self._callTestMethod(testMethod)
  File "C:\Users\ALEJANDRA\AppData\Local\Programs\Python\Python38\lib\unittest\case.py", line 633, in _callTestMethod
    method()
  File "c:\users\alejandra\desktop\uni\segundo\software_devel\g89.2022.t01.fp\target\venv\build\cpython-3.8.0.final.0\lib\site-packages\freezegun\api.py", line 789, in wrapper
    result = func(*args, **kwargs)
  File "c:\users\alejandra\desktop\uni\segundo\software_devel\g89.2022.t01.fp\src\unittest\python\test_get_vaccine_date_tests.py", line 293, in test_get_vaccine_date_no_ok_invalid_format_month_exceed
    my_manager.get_vaccine_date(file_test, date_invalid)
TypeError: get_vaccine_date() takes 2 positional arguments but 3 were given

======================================================================
ERROR [0.004s]: test_get_vaccine_date_no_ok_invalid_format_no_days (test_get_vaccine_date_tests.TestGetVaccineDate)
Test the get vaccine date method with an invalid format
----------------------------------------------------------------------
Traceback (most recent call last):
  File "C:\Users\ALEJANDRA\AppData\Local\Programs\Python\Python38\lib\unittest\case.py", line 60, in testPartExecutor
    yield
  File "C:\Users\ALEJANDRA\AppData\Local\Programs\Python\Python38\lib\unittest\case.py", line 676, in run
    self._callTestMethod(testMethod)
  File "C:\Users\ALEJANDRA\AppData\Local\Programs\Python\Python38\lib\unittest\case.py", line 633, in _callTestMethod
    method()
  File "c:\users\alejandra\desktop\uni\segundo\software_devel\g89.2022.t01.fp\target\venv\build\cpython-3.8.0.final.0\lib\site-packages\freezegun\api.py", line 789, in wrapper
    result = func(*args, **kwargs)
  File "c:\users\alejandra\desktop\uni\segundo\software_devel\g89.2022.t01.fp\src\unittest\python\test_get_vaccine_date_tests.py", line 447, in test_get_vaccine_date_no_ok_invalid_format_no_days
    my_manager.get_vaccine_date(file_test, date_invalid)
TypeError: get_vaccine_date() takes 2 positional arguments but 3 were given

======================================================================
ERROR [0.005s]: test_get_vaccine_date_no_ok_invalid_format_no_month (test_get_vaccine_date_tests.TestGetVaccineDate)
Test the get vaccine date method with an invalid format
----------------------------------------------------------------------
Traceback (most recent call last):
  File "C:\Users\ALEJANDRA\AppData\Local\Programs\Python\Python38\lib\unittest\case.py", line 60, in testPartExecutor
    yield
  File "C:\Users\ALEJANDRA\AppData\Local\Programs\Python\Python38\lib\unittest\case.py", line 676, in run
    self._callTestMethod(testMethod)
  File "C:\Users\ALEJANDRA\AppData\Local\Programs\Python\Python38\lib\unittest\case.py", line 633, in _callTestMethod
    method()
  File "c:\users\alejandra\desktop\uni\segundo\software_devel\g89.2022.t01.fp\target\venv\build\cpython-3.8.0.final.0\lib\site-packages\freezegun\api.py", line 789, in wrapper
    result = func(*args, **kwargs)
  File "c:\users\alejandra\desktop\uni\segundo\software_devel\g89.2022.t01.fp\src\unittest\python\test_get_vaccine_date_tests.py", line 425, in test_get_vaccine_date_no_ok_invalid_format_no_month
    my_manager.get_vaccine_date(file_test, date_invalid)
TypeError: get_vaccine_date() takes 2 positional arguments but 3 were given

======================================================================
ERROR [0.005s]: test_get_vaccine_date_no_ok_invalid_format_no_year (test_get_vaccine_date_tests.TestGetVaccineDate)
Test the get vaccine date method with an invalid format
----------------------------------------------------------------------
Traceback (most recent call last):
  File "C:\Users\ALEJANDRA\AppData\Local\Programs\Python\Python38\lib\unittest\case.py", line 60, in testPartExecutor
    yield
  File "C:\Users\ALEJANDRA\AppData\Local\Programs\Python\Python38\lib\unittest\case.py", line 676, in run
    self._callTestMethod(testMethod)
  File "C:\Users\ALEJANDRA\AppData\Local\Programs\Python\Python38\lib\unittest\case.py", line 633, in _callTestMethod
    method()
  File "c:\users\alejandra\desktop\uni\segundo\software_devel\g89.2022.t01.fp\target\venv\build\cpython-3.8.0.final.0\lib\site-packages\freezegun\api.py", line 789, in wrapper
    result = func(*args, **kwargs)
  File "c:\users\alejandra\desktop\uni\segundo\software_devel\g89.2022.t01.fp\src\unittest\python\test_get_vaccine_date_tests.py", line 403, in test_get_vaccine_date_no_ok_invalid_format_no_year
    my_manager.get_vaccine_date(file_test, date_invalid)
TypeError: get_vaccine_date() takes 2 positional arguments but 3 were given

======================================================================
ERROR [0.005s]: test_get_vaccine_date_no_ok_invalid_format_one_char_less (test_get_vaccine_date_tests.TestGetVaccineDate)
Test the get vaccine date method with an invalid format
----------------------------------------------------------------------
Traceback (most recent call last):
  File "C:\Users\ALEJANDRA\AppData\Local\Programs\Python\Python38\lib\unittest\case.py", line 60, in testPartExecutor
    yield
  File "C:\Users\ALEJANDRA\AppData\Local\Programs\Python\Python38\lib\unittest\case.py", line 676, in run
    self._callTestMethod(testMethod)
  File "C:\Users\ALEJANDRA\AppData\Local\Programs\Python\Python38\lib\unittest\case.py", line 633, in _callTestMethod
    method()
  File "c:\users\alejandra\desktop\uni\segundo\software_devel\g89.2022.t01.fp\target\venv\build\cpython-3.8.0.final.0\lib\site-packages\freezegun\api.py", line 789, in wrapper
    result = func(*args, **kwargs)
  File "c:\users\alejandra\desktop\uni\segundo\software_devel\g89.2022.t01.fp\src\unittest\python\test_get_vaccine_date_tests.py", line 227, in test_get_vaccine_date_no_ok_invalid_format_one_char_less
    my_manager.get_vaccine_date(file_test, date_one_char_less)
TypeError: get_vaccine_date() takes 2 positional arguments but 3 were given

======================================================================
ERROR [0.006s]: test_get_vaccine_date_no_ok_invalid_format_one_char_more (test_get_vaccine_date_tests.TestGetVaccineDate)
Test the get vaccine date method with an invalid format
----------------------------------------------------------------------
Traceback (most recent call last):
  File "C:\Users\ALEJANDRA\AppData\Local\Programs\Python\Python38\lib\unittest\case.py", line 60, in testPartExecutor
    yield
  File "C:\Users\ALEJANDRA\AppData\Local\Programs\Python\Python38\lib\unittest\case.py", line 676, in run
    self._callTestMethod(testMethod)
  File "C:\Users\ALEJANDRA\AppData\Local\Programs\Python\Python38\lib\unittest\case.py", line 633, in _callTestMethod
    method()
  File "c:\users\alejandra\desktop\uni\segundo\software_devel\g89.2022.t01.fp\target\venv\build\cpython-3.8.0.final.0\lib\site-packages\freezegun\api.py", line 789, in wrapper
    result = func(*args, **kwargs)
  File "c:\users\alejandra\desktop\uni\segundo\software_devel\g89.2022.t01.fp\src\unittest\python\test_get_vaccine_date_tests.py", line 249, in test_get_vaccine_date_no_ok_invalid_format_one_char_more
    my_manager.get_vaccine_date(file_test, date_one_char_more)
TypeError: get_vaccine_date() takes 2 positional arguments but 3 were given

======================================================================
ERROR [0.005s]: test_get_vaccine_date_no_ok_invalid_format_year_0 (test_get_vaccine_date_tests.TestGetVaccineDate)
Test the get vaccine date method with an invalid format
----------------------------------------------------------------------
Traceback (most recent call last):
  File "C:\Users\ALEJANDRA\AppData\Local\Programs\Python\Python38\lib\unittest\case.py", line 60, in testPartExecutor
    yield
  File "C:\Users\ALEJANDRA\AppData\Local\Programs\Python\Python38\lib\unittest\case.py", line 676, in run
    self._callTestMethod(testMethod)
  File "C:\Users\ALEJANDRA\AppData\Local\Programs\Python\Python38\lib\unittest\case.py", line 633, in _callTestMethod
    method()
  File "c:\users\alejandra\desktop\uni\segundo\software_devel\g89.2022.t01.fp\target\venv\build\cpython-3.8.0.final.0\lib\site-packages\freezegun\api.py", line 789, in wrapper
    result = func(*args, **kwargs)
  File "c:\users\alejandra\desktop\uni\segundo\software_devel\g89.2022.t01.fp\src\unittest\python\test_get_vaccine_date_tests.py", line 381, in test_get_vaccine_date_no_ok_invalid_format_year_0
    my_manager.get_vaccine_date(file_test, date_invalid)
TypeError: get_vaccine_date() takes 2 positional arguments but 3 were given

======================================================================
ERROR [0.005s]: test_get_vaccine_date_no_ok_no_quotes (test_get_vaccine_date_tests.TestGetVaccineDate)
no quotes , not valid
----------------------------------------------------------------------
Traceback (most recent call last):
  File "C:\Users\ALEJANDRA\AppData\Local\Programs\Python\Python38\lib\unittest\case.py", line 60, in testPartExecutor
    yield
  File "C:\Users\ALEJANDRA\AppData\Local\Programs\Python\Python38\lib\unittest\case.py", line 676, in run
    self._callTestMethod(testMethod)
  File "C:\Users\ALEJANDRA\AppData\Local\Programs\Python\Python38\lib\unittest\case.py", line 633, in _callTestMethod
    method()
  File "c:\users\alejandra\desktop\uni\segundo\software_devel\g89.2022.t01.fp\target\venv\build\cpython-3.8.0.final.0\lib\site-packages\freezegun\api.py", line 789, in wrapper
    result = func(*args, **kwargs)
  File "c:\users\alejandra\desktop\uni\segundo\software_devel\g89.2022.t01.fp\src\unittest\python\test_get_vaccine_date_tests.py", line 134, in test_get_vaccine_date_no_ok_no_quotes
    my_manager.get_vaccine_date(file_test, DATE)
TypeError: get_vaccine_date() takes 2 positional arguments but 3 were given

======================================================================
ERROR [0.007s]: test_get_vaccine_date_no_ok_outdated_date (test_get_vaccine_date_tests.TestGetVaccineDate)
Test the get vaccine date method with an outdated date
----------------------------------------------------------------------
Traceback (most recent call last):
  File "C:\Users\ALEJANDRA\AppData\Local\Programs\Python\Python38\lib\unittest\case.py", line 60, in testPartExecutor
    yield
  File "C:\Users\ALEJANDRA\AppData\Local\Programs\Python\Python38\lib\unittest\case.py", line 676, in run
    self._callTestMethod(testMethod)
  File "C:\Users\ALEJANDRA\AppData\Local\Programs\Python\Python38\lib\unittest\case.py", line 633, in _callTestMethod
    method()
  File "c:\users\alejandra\desktop\uni\segundo\software_devel\g89.2022.t01.fp\target\venv\build\cpython-3.8.0.final.0\lib\site-packages\freezegun\api.py", line 789, in wrapper
    result = func(*args, **kwargs)
  File "c:\users\alejandra\desktop\uni\segundo\software_devel\g89.2022.t01.fp\src\unittest\python\test_get_vaccine_date_tests.py", line 205, in test_get_vaccine_date_no_ok_outdated_date
    my_manager.get_vaccine_date(file_test, yesterday_date)
TypeError: get_vaccine_date() takes 2 positional arguments but 3 were given

======================================================================
ERROR [0.055s]: test_get_vaccine_date_no_ok_parameter (test_get_vaccine_date_tests.TestGetVaccineDate)
tests no ok
----------------------------------------------------------------------
Traceback (most recent call last):
  File "c:\users\alejandra\desktop\uni\segundo\software_devel\g89.2022.t01.fp\src\main\python\uc3m_care\storage\json_store.py", line 31, in save
    with open(self._FILE_PATH, "w", encoding="utf-8", newline="") as file:
FileNotFoundError: [Errno 2] No such file or directory: 'C:\\Users\\ALEJANDRADesktop/uni/segundo/software_devel/G89.2022.T01.FP/src/JsonFilesstore_patient.json'

The above exception was the direct cause of the following exception:

Traceback (most recent call last):
  File "C:\Users\ALEJANDRA\AppData\Local\Programs\Python\Python38\lib\unittest\case.py", line 60, in testPartExecutor
    yield
  File "C:\Users\ALEJANDRA\AppData\Local\Programs\Python\Python38\lib\unittest\case.py", line 676, in run
    self._callTestMethod(testMethod)
  File "C:\Users\ALEJANDRA\AppData\Local\Programs\Python\Python38\lib\unittest\case.py", line 633, in _callTestMethod
    method()
  File "c:\users\alejandra\desktop\uni\segundo\software_devel\g89.2022.t01.fp\target\venv\build\cpython-3.8.0.final.0\lib\site-packages\freezegun\api.py", line 789, in wrapper
    result = func(*args, **kwargs)
  File "c:\users\alejandra\desktop\uni\segundo\software_devel\g89.2022.t01.fp\src\unittest\python\test_get_vaccine_date_tests.py", line 84, in test_get_vaccine_date_no_ok_parameter
    my_manager.request_vaccination_id("78924cb0-075a-4099-a3ee-f3b562e805b9",
  File "c:\users\alejandra\desktop\uni\segundo\software_devel\g89.2022.t01.fp\src\main\python\uc3m_care\vaccine_manager.py", line 28, in request_vaccination_id
    my_patient.save_patient()
  File "c:\users\alejandra\desktop\uni\segundo\software_devel\g89.2022.t01.fp\src\main\python\uc3m_care\data\vaccine_patient_register.py", line 121, in save_patient
    patients_store.add_item(self)
  File "c:\users\alejandra\desktop\uni\segundo\software_devel\g89.2022.t01.fp\src\main\python\uc3m_care\storage\patients_json_store.py", line 34, in add_item
    super().add_item(item)
  File "c:\users\alejandra\desktop\uni\segundo\software_devel\g89.2022.t01.fp\src\main\python\uc3m_care\storage\json_store.py", line 40, in add_item
    self.save()
  File "c:\users\alejandra\desktop\uni\segundo\software_devel\g89.2022.t01.fp\src\main\python\uc3m_care\storage\json_store.py", line 34, in save
    raise VaccineManagementException("Wrong file or file path") from ex
uc3m_care.exception.vaccine_management_exception.VaccineManagementException: Wrong file or file path

======================================================================
ERROR [0.013s]: test_get_vaccine_date_ok (test_get_vaccine_date_tests.TestGetVaccineDate)
test ok
----------------------------------------------------------------------
Traceback (most recent call last):
  File "c:\users\alejandra\desktop\uni\segundo\software_devel\g89.2022.t01.fp\src\main\python\uc3m_care\storage\json_store.py", line 31, in save
    with open(self._FILE_PATH, "w", encoding="utf-8", newline="") as file:
FileNotFoundError: [Errno 2] No such file or directory: 'C:\\Users\\ALEJANDRADesktop/uni/segundo/software_devel/G89.2022.T01.FP/src/JsonFilesstore_patient.json'

The above exception was the direct cause of the following exception:

Traceback (most recent call last):
  File "C:\Users\ALEJANDRA\AppData\Local\Programs\Python\Python38\lib\unittest\case.py", line 60, in testPartExecutor
    yield
  File "C:\Users\ALEJANDRA\AppData\Local\Programs\Python\Python38\lib\unittest\case.py", line 676, in run
    self._callTestMethod(testMethod)
  File "C:\Users\ALEJANDRA\AppData\Local\Programs\Python\Python38\lib\unittest\case.py", line 633, in _callTestMethod
    method()
  File "c:\users\alejandra\desktop\uni\segundo\software_devel\g89.2022.t01.fp\target\venv\build\cpython-3.8.0.final.0\lib\site-packages\freezegun\api.py", line 789, in wrapper
    result = func(*args, **kwargs)
  File "c:\users\alejandra\desktop\uni\segundo\software_devel\g89.2022.t01.fp\src\unittest\python\test_get_vaccine_date_tests.py", line 65, in test_get_vaccine_date_ok
    my_manager.request_vaccination_id("78924cb0-075a-4099-a3ee-f3b562e805b9",
  File "c:\users\alejandra\desktop\uni\segundo\software_devel\g89.2022.t01.fp\src\main\python\uc3m_care\vaccine_manager.py", line 28, in request_vaccination_id
    my_patient.save_patient()
  File "c:\users\alejandra\desktop\uni\segundo\software_devel\g89.2022.t01.fp\src\main\python\uc3m_care\data\vaccine_patient_register.py", line 121, in save_patient
    patients_store.add_item(self)
  File "c:\users\alejandra\desktop\uni\segundo\software_devel\g89.2022.t01.fp\src\main\python\uc3m_care\storage\patients_json_store.py", line 34, in add_item
    super().add_item(item)
  File "c:\users\alejandra\desktop\uni\segundo\software_devel\g89.2022.t01.fp\src\main\python\uc3m_care\storage\json_store.py", line 40, in add_item
    self.save()
  File "c:\users\alejandra\desktop\uni\segundo\software_devel\g89.2022.t01.fp\src\main\python\uc3m_care\storage\json_store.py", line 34, in save
    raise VaccineManagementException("Wrong file or file path") from ex
uc3m_care.exception.vaccine_management_exception.VaccineManagementException: Wrong file or file path

======================================================================
ERROR [0.019s]: test__add_family_valid_request_vaccination (test_request_vaccine_tests.TestRequestVacID)
Test 21 , patient Regular and family registered in store
----------------------------------------------------------------------
Traceback (most recent call last):
  File "c:\users\alejandra\desktop\uni\segundo\software_devel\g89.2022.t01.fp\src\main\python\uc3m_care\storage\json_store.py", line 31, in save
    with open(self._FILE_PATH, "w", encoding="utf-8", newline="") as file:
FileNotFoundError: [Errno 2] No such file or directory: 'C:\\Users\\ALEJANDRADesktop/uni/segundo/software_devel/G89.2022.T01.FP/src/JsonFilesstore_patient.json'

The above exception was the direct cause of the following exception:

Traceback (most recent call last):
  File "C:\Users\ALEJANDRA\AppData\Local\Programs\Python\Python38\lib\unittest\case.py", line 60, in testPartExecutor
    yield
  File "C:\Users\ALEJANDRA\AppData\Local\Programs\Python\Python38\lib\unittest\case.py", line 676, in run
    self._callTestMethod(testMethod)
  File "C:\Users\ALEJANDRA\AppData\Local\Programs\Python\Python38\lib\unittest\case.py", line 633, in _callTestMethod
    method()
  File "c:\users\alejandra\desktop\uni\segundo\software_devel\g89.2022.t01.fp\target\venv\build\cpython-3.8.0.final.0\lib\site-packages\freezegun\api.py", line 789, in wrapper
    result = func(*args, **kwargs)
  File "c:\users\alejandra\desktop\uni\segundo\software_devel\g89.2022.t01.fp\src\unittest\python\test_request_vaccine_tests.py", line 157, in test__add_family_valid_request_vaccination
    file_store.empty_json_file()
  File "c:\users\alejandra\desktop\uni\segundo\software_devel\g89.2022.t01.fp\src\main\python\uc3m_care\storage\json_store.py", line 71, in empty_json_file
    self.save()
  File "c:\users\alejandra\desktop\uni\segundo\software_devel\g89.2022.t01.fp\src\main\python\uc3m_care\storage\json_store.py", line 34, in save
    raise VaccineManagementException("Wrong file or file path") from ex
uc3m_care.exception.vaccine_management_exception.VaccineManagementException: Wrong file or file path

======================================================================
ERROR [0.008s]: test__duplicate_valid_request_vaccination (test_request_vaccine_tests.TestRequestVacID)
Test 20 , patient id is registered in store
----------------------------------------------------------------------
Traceback (most recent call last):
  File "c:\users\alejandra\desktop\uni\segundo\software_devel\g89.2022.t01.fp\src\main\python\uc3m_care\storage\json_store.py", line 31, in save
    with open(self._FILE_PATH, "w", encoding="utf-8", newline="") as file:
FileNotFoundError: [Errno 2] No such file or directory: 'C:\\Users\\ALEJANDRADesktop/uni/segundo/software_devel/G89.2022.T01.FP/src/JsonFilesstore_patient.json'

The above exception was the direct cause of the following exception:

Traceback (most recent call last):
  File "C:\Users\ALEJANDRA\AppData\Local\Programs\Python\Python38\lib\unittest\case.py", line 60, in testPartExecutor
    yield
  File "C:\Users\ALEJANDRA\AppData\Local\Programs\Python\Python38\lib\unittest\case.py", line 676, in run
    self._callTestMethod(testMethod)
  File "C:\Users\ALEJANDRA\AppData\Local\Programs\Python\Python38\lib\unittest\case.py", line 633, in _callTestMethod
    method()
  File "c:\users\alejandra\desktop\uni\segundo\software_devel\g89.2022.t01.fp\src\unittest\python\test_request_vaccine_tests.py", line 142, in test__duplicate_valid_request_vaccination
    value = my_request.request_vaccination_id("a729d963-e0dd-47d0-8bc6-b6c595ad0098",
  File "c:\users\alejandra\desktop\uni\segundo\software_devel\g89.2022.t01.fp\src\main\python\uc3m_care\vaccine_manager.py", line 28, in request_vaccination_id
    my_patient.save_patient()
  File "c:\users\alejandra\desktop\uni\segundo\software_devel\g89.2022.t01.fp\src\main\python\uc3m_care\data\vaccine_patient_register.py", line 121, in save_patient
    patients_store.add_item(self)
  File "c:\users\alejandra\desktop\uni\segundo\software_devel\g89.2022.t01.fp\src\main\python\uc3m_care\storage\patients_json_store.py", line 34, in add_item
    super().add_item(item)
  File "c:\users\alejandra\desktop\uni\segundo\software_devel\g89.2022.t01.fp\src\main\python\uc3m_care\storage\json_store.py", line 40, in add_item
    self.save()
  File "c:\users\alejandra\desktop\uni\segundo\software_devel\g89.2022.t01.fp\src\main\python\uc3m_care\storage\json_store.py", line 34, in save
    raise VaccineManagementException("Wrong file or file path") from ex
uc3m_care.exception.vaccine_management_exception.VaccineManagementException: Wrong file or file path

======================================================================
ERROR [0.007s]: test_parametrized_not_valid_request_vaccination (test_request_vaccine_tests.TestRequestVacID)
Method for testing request_vaccination_id: invalid cases
----------------------------------------------------------------------
Traceback (most recent call last):
  File "c:\users\alejandra\desktop\uni\segundo\software_devel\g89.2022.t01.fp\src\main\python\uc3m_care\storage\json_store.py", line 31, in save
    with open(self._FILE_PATH, "w", encoding="utf-8", newline="") as file:
FileNotFoundError: [Errno 2] No such file or directory: 'C:\\Users\\ALEJANDRADesktop/uni/segundo/software_devel/G89.2022.T01.FP/src/JsonFilesstore_patient.json'

The above exception was the direct cause of the following exception:

Traceback (most recent call last):
  File "C:\Users\ALEJANDRA\AppData\Local\Programs\Python\Python38\lib\unittest\case.py", line 60, in testPartExecutor
    yield
  File "C:\Users\ALEJANDRA\AppData\Local\Programs\Python\Python38\lib\unittest\case.py", line 676, in run
    self._callTestMethod(testMethod)
  File "C:\Users\ALEJANDRA\AppData\Local\Programs\Python\Python38\lib\unittest\case.py", line 633, in _callTestMethod
    method()
  File "c:\users\alejandra\desktop\uni\segundo\software_devel\g89.2022.t01.fp\src\unittest\python\test_request_vaccine_tests.py", line 123, in test_parametrized_not_valid_request_vaccination
    file_store.empty_json_file()
  File "c:\users\alejandra\desktop\uni\segundo\software_devel\g89.2022.t01.fp\src\main\python\uc3m_care\storage\json_store.py", line 71, in empty_json_file
    self.save()
  File "c:\users\alejandra\desktop\uni\segundo\software_devel\g89.2022.t01.fp\src\main\python\uc3m_care\storage\json_store.py", line 34, in save
    raise VaccineManagementException("Wrong file or file path") from ex
uc3m_care.exception.vaccine_management_exception.VaccineManagementException: Wrong file or file path

======================================================================
ERROR [0.000s]: test_parametrized_valid_request_vaccination (test_request_vaccine_tests.TestRequestVacID) (test='test_1')
Parametrized tests: valid cases
----------------------------------------------------------------------
Traceback (most recent call last):
  File "c:\users\alejandra\desktop\uni\segundo\software_devel\g89.2022.t01.fp\src\main\python\uc3m_care\storage\json_store.py", line 31, in save
    with open(self._FILE_PATH, "w", encoding="utf-8", newline="") as file:
FileNotFoundError: [Errno 2] No such file or directory: 'C:\\Users\\ALEJANDRADesktop/uni/segundo/software_devel/G89.2022.T01.FP/src/JsonFilesstore_patient.json'

The above exception was the direct cause of the following exception:

Traceback (most recent call last):
  File "C:\Users\ALEJANDRA\AppData\Local\Programs\Python\Python38\lib\unittest\case.py", line 60, in testPartExecutor
    yield
  File "C:\Users\ALEJANDRA\AppData\Local\Programs\Python\Python38\lib\unittest\case.py", line 582, in subTest
    yield
  File "c:\users\alejandra\desktop\uni\segundo\software_devel\g89.2022.t01.fp\src\unittest\python\test_request_vaccine_tests.py", line 115, in test_parametrized_valid_request_vaccination
    value = my_request.request_vaccination_id(patient_id, name_surname,
  File "c:\users\alejandra\desktop\uni\segundo\software_devel\g89.2022.t01.fp\src\main\python\uc3m_care\vaccine_manager.py", line 28, in request_vaccination_id
    my_patient.save_patient()
  File "c:\users\alejandra\desktop\uni\segundo\software_devel\g89.2022.t01.fp\src\main\python\uc3m_care\data\vaccine_patient_register.py", line 121, in save_patient
    patients_store.add_item(self)
  File "c:\users\alejandra\desktop\uni\segundo\software_devel\g89.2022.t01.fp\src\main\python\uc3m_care\storage\patients_json_store.py", line 34, in add_item
    super().add_item(item)
  File "c:\users\alejandra\desktop\uni\segundo\software_devel\g89.2022.t01.fp\src\main\python\uc3m_care\storage\json_store.py", line 40, in add_item
    self.save()
  File "c:\users\alejandra\desktop\uni\segundo\software_devel\g89.2022.t01.fp\src\main\python\uc3m_care\storage\json_store.py", line 34, in save
    raise VaccineManagementException("Wrong file or file path") from ex
uc3m_care.exception.vaccine_management_exception.VaccineManagementException: Wrong file or file path

======================================================================
ERROR [0.000s]: test_parametrized_valid_request_vaccination (test_request_vaccine_tests.TestRequestVacID) (test='test_2')
Parametrized tests: valid cases
----------------------------------------------------------------------
Traceback (most recent call last):
  File "c:\users\alejandra\desktop\uni\segundo\software_devel\g89.2022.t01.fp\src\main\python\uc3m_care\storage\json_store.py", line 31, in save
    with open(self._FILE_PATH, "w", encoding="utf-8", newline="") as file:
FileNotFoundError: [Errno 2] No such file or directory: 'C:\\Users\\ALEJANDRADesktop/uni/segundo/software_devel/G89.2022.T01.FP/src/JsonFilesstore_patient.json'

The above exception was the direct cause of the following exception:

Traceback (most recent call last):
  File "C:\Users\ALEJANDRA\AppData\Local\Programs\Python\Python38\lib\unittest\case.py", line 60, in testPartExecutor
    yield
  File "C:\Users\ALEJANDRA\AppData\Local\Programs\Python\Python38\lib\unittest\case.py", line 582, in subTest
    yield
  File "c:\users\alejandra\desktop\uni\segundo\software_devel\g89.2022.t01.fp\src\unittest\python\test_request_vaccine_tests.py", line 115, in test_parametrized_valid_request_vaccination
    value = my_request.request_vaccination_id(patient_id, name_surname,
  File "c:\users\alejandra\desktop\uni\segundo\software_devel\g89.2022.t01.fp\src\main\python\uc3m_care\vaccine_manager.py", line 28, in request_vaccination_id
    my_patient.save_patient()
  File "c:\users\alejandra\desktop\uni\segundo\software_devel\g89.2022.t01.fp\src\main\python\uc3m_care\data\vaccine_patient_register.py", line 121, in save_patient
    patients_store.add_item(self)
  File "c:\users\alejandra\desktop\uni\segundo\software_devel\g89.2022.t01.fp\src\main\python\uc3m_care\storage\patients_json_store.py", line 34, in add_item
    super().add_item(item)
  File "c:\users\alejandra\desktop\uni\segundo\software_devel\g89.2022.t01.fp\src\main\python\uc3m_care\storage\json_store.py", line 40, in add_item
    self.save()
  File "c:\users\alejandra\desktop\uni\segundo\software_devel\g89.2022.t01.fp\src\main\python\uc3m_care\storage\json_store.py", line 34, in save
    raise VaccineManagementException("Wrong file or file path") from ex
uc3m_care.exception.vaccine_management_exception.VaccineManagementException: Wrong file or file path

======================================================================
ERROR [0.000s]: test_parametrized_valid_request_vaccination (test_request_vaccine_tests.TestRequestVacID) (test='test_3')
Parametrized tests: valid cases
----------------------------------------------------------------------
Traceback (most recent call last):
  File "c:\users\alejandra\desktop\uni\segundo\software_devel\g89.2022.t01.fp\src\main\python\uc3m_care\storage\json_store.py", line 31, in save
    with open(self._FILE_PATH, "w", encoding="utf-8", newline="") as file:
FileNotFoundError: [Errno 2] No such file or directory: 'C:\\Users\\ALEJANDRADesktop/uni/segundo/software_devel/G89.2022.T01.FP/src/JsonFilesstore_patient.json'

The above exception was the direct cause of the following exception:

Traceback (most recent call last):
  File "C:\Users\ALEJANDRA\AppData\Local\Programs\Python\Python38\lib\unittest\case.py", line 60, in testPartExecutor
    yield
  File "C:\Users\ALEJANDRA\AppData\Local\Programs\Python\Python38\lib\unittest\case.py", line 582, in subTest
    yield
  File "c:\users\alejandra\desktop\uni\segundo\software_devel\g89.2022.t01.fp\src\unittest\python\test_request_vaccine_tests.py", line 115, in test_parametrized_valid_request_vaccination
    value = my_request.request_vaccination_id(patient_id, name_surname,
  File "c:\users\alejandra\desktop\uni\segundo\software_devel\g89.2022.t01.fp\src\main\python\uc3m_care\vaccine_manager.py", line 28, in request_vaccination_id
    my_patient.save_patient()
  File "c:\users\alejandra\desktop\uni\segundo\software_devel\g89.2022.t01.fp\src\main\python\uc3m_care\data\vaccine_patient_register.py", line 121, in save_patient
    patients_store.add_item(self)
  File "c:\users\alejandra\desktop\uni\segundo\software_devel\g89.2022.t01.fp\src\main\python\uc3m_care\storage\patients_json_store.py", line 34, in add_item
    super().add_item(item)
  File "c:\users\alejandra\desktop\uni\segundo\software_devel\g89.2022.t01.fp\src\main\python\uc3m_care\storage\json_store.py", line 40, in add_item
    self.save()
  File "c:\users\alejandra\desktop\uni\segundo\software_devel\g89.2022.t01.fp\src\main\python\uc3m_care\storage\json_store.py", line 34, in save
    raise VaccineManagementException("Wrong file or file path") from ex
uc3m_care.exception.vaccine_management_exception.VaccineManagementException: Wrong file or file path

======================================================================
ERROR [0.054s]: test_parametrized_valid_request_vaccination (test_request_vaccine_tests.TestRequestVacID) (test='test_4')
Parametrized tests: valid cases
----------------------------------------------------------------------
Traceback (most recent call last):
  File "c:\users\alejandra\desktop\uni\segundo\software_devel\g89.2022.t01.fp\src\main\python\uc3m_care\storage\json_store.py", line 31, in save
    with open(self._FILE_PATH, "w", encoding="utf-8", newline="") as file:
FileNotFoundError: [Errno 2] No such file or directory: 'C:\\Users\\ALEJANDRADesktop/uni/segundo/software_devel/G89.2022.T01.FP/src/JsonFilesstore_patient.json'

The above exception was the direct cause of the following exception:

Traceback (most recent call last):
  File "C:\Users\ALEJANDRA\AppData\Local\Programs\Python\Python38\lib\unittest\case.py", line 60, in testPartExecutor
    yield
  File "C:\Users\ALEJANDRA\AppData\Local\Programs\Python\Python38\lib\unittest\case.py", line 582, in subTest
    yield
  File "c:\users\alejandra\desktop\uni\segundo\software_devel\g89.2022.t01.fp\src\unittest\python\test_request_vaccine_tests.py", line 115, in test_parametrized_valid_request_vaccination
    value = my_request.request_vaccination_id(patient_id, name_surname,
  File "c:\users\alejandra\desktop\uni\segundo\software_devel\g89.2022.t01.fp\src\main\python\uc3m_care\vaccine_manager.py", line 28, in request_vaccination_id
    my_patient.save_patient()
  File "c:\users\alejandra\desktop\uni\segundo\software_devel\g89.2022.t01.fp\src\main\python\uc3m_care\data\vaccine_patient_register.py", line 121, in save_patient
    patients_store.add_item(self)
  File "c:\users\alejandra\desktop\uni\segundo\software_devel\g89.2022.t01.fp\src\main\python\uc3m_care\storage\patients_json_store.py", line 34, in add_item
    super().add_item(item)
  File "c:\users\alejandra\desktop\uni\segundo\software_devel\g89.2022.t01.fp\src\main\python\uc3m_care\storage\json_store.py", line 40, in add_item
    self.save()
  File "c:\users\alejandra\desktop\uni\segundo\software_devel\g89.2022.t01.fp\src\main\python\uc3m_care\storage\json_store.py", line 34, in save
    raise VaccineManagementException("Wrong file or file path") from ex
uc3m_care.exception.vaccine_management_exception.VaccineManagementException: Wrong file or file path

======================================================================
ERROR [0.013s]: test_request_vaccination_id_ok (test_request_vaccine_tests.TestRequestVacID)
Test OK
----------------------------------------------------------------------
Traceback (most recent call last):
  File "c:\users\alejandra\desktop\uni\segundo\software_devel\g89.2022.t01.fp\src\main\python\uc3m_care\storage\json_store.py", line 31, in save
    with open(self._FILE_PATH, "w", encoding="utf-8", newline="") as file:
FileNotFoundError: [Errno 2] No such file or directory: 'C:\\Users\\ALEJANDRADesktop/uni/segundo/software_devel/G89.2022.T01.FP/src/JsonFilesstore_patient.json'

The above exception was the direct cause of the following exception:

Traceback (most recent call last):
  File "C:\Users\ALEJANDRA\AppData\Local\Programs\Python\Python38\lib\unittest\case.py", line 60, in testPartExecutor
    yield
  File "C:\Users\ALEJANDRA\AppData\Local\Programs\Python\Python38\lib\unittest\case.py", line 676, in run
    self._callTestMethod(testMethod)
  File "C:\Users\ALEJANDRA\AppData\Local\Programs\Python\Python38\lib\unittest\case.py", line 633, in _callTestMethod
    method()
  File "c:\users\alejandra\desktop\uni\segundo\software_devel\g89.2022.t01.fp\target\venv\build\cpython-3.8.0.final.0\lib\site-packages\freezegun\api.py", line 789, in wrapper
    result = func(*args, **kwargs)
  File "c:\users\alejandra\desktop\uni\segundo\software_devel\g89.2022.t01.fp\src\unittest\python\test_request_vaccine_tests.py", line 175, in test_request_vaccination_id_ok
    value = my_request.request_vaccination_id("bb5dbd6f-d8b4-413f-8eb9-dd262cfc54e0",
  File "c:\users\alejandra\desktop\uni\segundo\software_devel\g89.2022.t01.fp\src\main\python\uc3m_care\vaccine_manager.py", line 28, in request_vaccination_id
    my_patient.save_patient()
  File "c:\users\alejandra\desktop\uni\segundo\software_devel\g89.2022.t01.fp\src\main\python\uc3m_care\data\vaccine_patient_register.py", line 121, in save_patient
    patients_store.add_item(self)
  File "c:\users\alejandra\desktop\uni\segundo\software_devel\g89.2022.t01.fp\src\main\python\uc3m_care\storage\patients_json_store.py", line 34, in add_item
    super().add_item(item)
  File "c:\users\alejandra\desktop\uni\segundo\software_devel\g89.2022.t01.fp\src\main\python\uc3m_care\storage\json_store.py", line 40, in add_item
    self.save()
  File "c:\users\alejandra\desktop\uni\segundo\software_devel\g89.2022.t01.fp\src\main\python\uc3m_care\storage\json_store.py", line 34, in save
    raise VaccineManagementException("Wrong file or file path") from ex
uc3m_care.exception.vaccine_management_exception.VaccineManagementException: Wrong file or file path

======================================================================
ERROR [0.019s]: test_vaccine_patient_bad_date_signature (test_vaccine_patient_tests.TestVaccinePatient)
path signature is not valid format , only 63 chars
----------------------------------------------------------------------
Traceback (most recent call last):
  File "c:\users\alejandra\desktop\uni\segundo\software_devel\g89.2022.t01.fp\src\main\python\uc3m_care\storage\json_store.py", line 31, in save
    with open(self._FILE_PATH, "w", encoding="utf-8", newline="") as file:
FileNotFoundError: [Errno 2] No such file or directory: 'C:\\Users\\ALEJANDRADesktop/uni/segundo/software_devel/G89.2022.T01.FP/src/JsonFilesstore_patient.json'

The above exception was the direct cause of the following exception:

Traceback (most recent call last):
  File "C:\Users\ALEJANDRA\AppData\Local\Programs\Python\Python38\lib\unittest\case.py", line 60, in testPartExecutor
    yield
  File "C:\Users\ALEJANDRA\AppData\Local\Programs\Python\Python38\lib\unittest\case.py", line 672, in run
    self._callSetUp()
  File "C:\Users\ALEJANDRA\AppData\Local\Programs\Python\Python38\lib\unittest\case.py", line 630, in _callSetUp
    self.setUp()
  File "c:\users\alejandra\desktop\uni\segundo\software_devel\g89.2022.t01.fp\target\venv\build\cpython-3.8.0.final.0\lib\site-packages\freezegun\api.py", line 789, in wrapper
    result = func(*args, **kwargs)
  File "c:\users\alejandra\desktop\uni\segundo\software_devel\g89.2022.t01.fp\src\unittest\python\test_vaccine_patient_tests.py", line 26, in setUp
    my_manager.request_vaccination_id("78924cb0-075a-4099-a3ee-f3b562e805b9",
  File "c:\users\alejandra\desktop\uni\segundo\software_devel\g89.2022.t01.fp\src\main\python\uc3m_care\vaccine_manager.py", line 28, in request_vaccination_id
    my_patient.save_patient()
  File "c:\users\alejandra\desktop\uni\segundo\software_devel\g89.2022.t01.fp\src\main\python\uc3m_care\data\vaccine_patient_register.py", line 121, in save_patient
    patients_store.add_item(self)
  File "c:\users\alejandra\desktop\uni\segundo\software_devel\g89.2022.t01.fp\src\main\python\uc3m_care\storage\patients_json_store.py", line 34, in add_item
    super().add_item(item)
  File "c:\users\alejandra\desktop\uni\segundo\software_devel\g89.2022.t01.fp\src\main\python\uc3m_care\storage\json_store.py", line 40, in add_item
    self.save()
  File "c:\users\alejandra\desktop\uni\segundo\software_devel\g89.2022.t01.fp\src\main\python\uc3m_care\storage\json_store.py", line 34, in save
    raise VaccineManagementException("Wrong file or file path") from ex
uc3m_care.exception.vaccine_management_exception.VaccineManagementException: Wrong file or file path

======================================================================
ERROR [0.013s]: test_vaccine_patient_no_date (test_vaccine_patient_tests.TestVaccinePatient)
path signature is found , and date is not today
----------------------------------------------------------------------
Traceback (most recent call last):
  File "c:\users\alejandra\desktop\uni\segundo\software_devel\g89.2022.t01.fp\src\main\python\uc3m_care\storage\json_store.py", line 31, in save
    with open(self._FILE_PATH, "w", encoding="utf-8", newline="") as file:
FileNotFoundError: [Errno 2] No such file or directory: 'C:\\Users\\ALEJANDRADesktop/uni/segundo/software_devel/G89.2022.T01.FP/src/JsonFilesstore_patient.json'

The above exception was the direct cause of the following exception:

Traceback (most recent call last):
  File "C:\Users\ALEJANDRA\AppData\Local\Programs\Python\Python38\lib\unittest\case.py", line 60, in testPartExecutor
    yield
  File "C:\Users\ALEJANDRA\AppData\Local\Programs\Python\Python38\lib\unittest\case.py", line 672, in run
    self._callSetUp()
  File "C:\Users\ALEJANDRA\AppData\Local\Programs\Python\Python38\lib\unittest\case.py", line 630, in _callSetUp
    self.setUp()
  File "c:\users\alejandra\desktop\uni\segundo\software_devel\g89.2022.t01.fp\target\venv\build\cpython-3.8.0.final.0\lib\site-packages\freezegun\api.py", line 789, in wrapper
    result = func(*args, **kwargs)
  File "c:\users\alejandra\desktop\uni\segundo\software_devel\g89.2022.t01.fp\src\unittest\python\test_vaccine_patient_tests.py", line 26, in setUp
    my_manager.request_vaccination_id("78924cb0-075a-4099-a3ee-f3b562e805b9",
  File "c:\users\alejandra\desktop\uni\segundo\software_devel\g89.2022.t01.fp\src\main\python\uc3m_care\vaccine_manager.py", line 28, in request_vaccination_id
    my_patient.save_patient()
  File "c:\users\alejandra\desktop\uni\segundo\software_devel\g89.2022.t01.fp\src\main\python\uc3m_care\data\vaccine_patient_register.py", line 121, in save_patient
    patients_store.add_item(self)
  File "c:\users\alejandra\desktop\uni\segundo\software_devel\g89.2022.t01.fp\src\main\python\uc3m_care\storage\patients_json_store.py", line 34, in add_item
    super().add_item(item)
  File "c:\users\alejandra\desktop\uni\segundo\software_devel\g89.2022.t01.fp\src\main\python\uc3m_care\storage\json_store.py", line 40, in add_item
    self.save()
  File "c:\users\alejandra\desktop\uni\segundo\software_devel\g89.2022.t01.fp\src\main\python\uc3m_care\storage\json_store.py", line 34, in save
    raise VaccineManagementException("Wrong file or file path") from ex
uc3m_care.exception.vaccine_management_exception.VaccineManagementException: Wrong file or file path

======================================================================
ERROR [0.012s]: test_vaccine_patient_not_found_date_signature (test_vaccine_patient_tests.TestVaccinePatient)
path: signature is not found in store_date
----------------------------------------------------------------------
Traceback (most recent call last):
  File "c:\users\alejandra\desktop\uni\segundo\software_devel\g89.2022.t01.fp\src\main\python\uc3m_care\storage\json_store.py", line 31, in save
    with open(self._FILE_PATH, "w", encoding="utf-8", newline="") as file:
FileNotFoundError: [Errno 2] No such file or directory: 'C:\\Users\\ALEJANDRADesktop/uni/segundo/software_devel/G89.2022.T01.FP/src/JsonFilesstore_patient.json'

The above exception was the direct cause of the following exception:

Traceback (most recent call last):
  File "C:\Users\ALEJANDRA\AppData\Local\Programs\Python\Python38\lib\unittest\case.py", line 60, in testPartExecutor
    yield
  File "C:\Users\ALEJANDRA\AppData\Local\Programs\Python\Python38\lib\unittest\case.py", line 672, in run
    self._callSetUp()
  File "C:\Users\ALEJANDRA\AppData\Local\Programs\Python\Python38\lib\unittest\case.py", line 630, in _callSetUp
    self.setUp()
  File "c:\users\alejandra\desktop\uni\segundo\software_devel\g89.2022.t01.fp\target\venv\build\cpython-3.8.0.final.0\lib\site-packages\freezegun\api.py", line 789, in wrapper
    result = func(*args, **kwargs)
  File "c:\users\alejandra\desktop\uni\segundo\software_devel\g89.2022.t01.fp\src\unittest\python\test_vaccine_patient_tests.py", line 26, in setUp
    my_manager.request_vaccination_id("78924cb0-075a-4099-a3ee-f3b562e805b9",
  File "c:\users\alejandra\desktop\uni\segundo\software_devel\g89.2022.t01.fp\src\main\python\uc3m_care\vaccine_manager.py", line 28, in request_vaccination_id
    my_patient.save_patient()
  File "c:\users\alejandra\desktop\uni\segundo\software_devel\g89.2022.t01.fp\src\main\python\uc3m_care\data\vaccine_patient_register.py", line 121, in save_patient
    patients_store.add_item(self)
  File "c:\users\alejandra\desktop\uni\segundo\software_devel\g89.2022.t01.fp\src\main\python\uc3m_care\storage\patients_json_store.py", line 34, in add_item
    super().add_item(item)
  File "c:\users\alejandra\desktop\uni\segundo\software_devel\g89.2022.t01.fp\src\main\python\uc3m_care\storage\json_store.py", line 40, in add_item
    self.save()
  File "c:\users\alejandra\desktop\uni\segundo\software_devel\g89.2022.t01.fp\src\main\python\uc3m_care\storage\json_store.py", line 34, in save
    raise VaccineManagementException("Wrong file or file path") from ex
uc3m_care.exception.vaccine_management_exception.VaccineManagementException: Wrong file or file path

======================================================================
ERROR [0.010s]: test_vaccine_patient_ok (test_vaccine_patient_tests.TestVaccinePatient)
basic path , signature is found , and date = today
----------------------------------------------------------------------
Traceback (most recent call last):
  File "c:\users\alejandra\desktop\uni\segundo\software_devel\g89.2022.t01.fp\src\main\python\uc3m_care\storage\json_store.py", line 31, in save
    with open(self._FILE_PATH, "w", encoding="utf-8", newline="") as file:
FileNotFoundError: [Errno 2] No such file or directory: 'C:\\Users\\ALEJANDRADesktop/uni/segundo/software_devel/G89.2022.T01.FP/src/JsonFilesstore_patient.json'

The above exception was the direct cause of the following exception:

Traceback (most recent call last):
  File "C:\Users\ALEJANDRA\AppData\Local\Programs\Python\Python38\lib\unittest\case.py", line 60, in testPartExecutor
    yield
  File "C:\Users\ALEJANDRA\AppData\Local\Programs\Python\Python38\lib\unittest\case.py", line 672, in run
    self._callSetUp()
  File "C:\Users\ALEJANDRA\AppData\Local\Programs\Python\Python38\lib\unittest\case.py", line 630, in _callSetUp
    self.setUp()
  File "c:\users\alejandra\desktop\uni\segundo\software_devel\g89.2022.t01.fp\target\venv\build\cpython-3.8.0.final.0\lib\site-packages\freezegun\api.py", line 789, in wrapper
    result = func(*args, **kwargs)
  File "c:\users\alejandra\desktop\uni\segundo\software_devel\g89.2022.t01.fp\src\unittest\python\test_vaccine_patient_tests.py", line 26, in setUp
    my_manager.request_vaccination_id("78924cb0-075a-4099-a3ee-f3b562e805b9",
  File "c:\users\alejandra\desktop\uni\segundo\software_devel\g89.2022.t01.fp\src\main\python\uc3m_care\vaccine_manager.py", line 28, in request_vaccination_id
    my_patient.save_patient()
  File "c:\users\alejandra\desktop\uni\segundo\software_devel\g89.2022.t01.fp\src\main\python\uc3m_care\data\vaccine_patient_register.py", line 121, in save_patient
    patients_store.add_item(self)
  File "c:\users\alejandra\desktop\uni\segundo\software_devel\g89.2022.t01.fp\src\main\python\uc3m_care\storage\patients_json_store.py", line 34, in add_item
    super().add_item(item)
  File "c:\users\alejandra\desktop\uni\segundo\software_devel\g89.2022.t01.fp\src\main\python\uc3m_care\storage\json_store.py", line 40, in add_item
    self.save()
  File "c:\users\alejandra\desktop\uni\segundo\software_devel\g89.2022.t01.fp\src\main\python\uc3m_care\storage\json_store.py", line 34, in save
    raise VaccineManagementException("Wrong file or file path") from ex
uc3m_care.exception.vaccine_management_exception.VaccineManagementException: Wrong file or file path

======================================================================
ERROR [0.011s]: test_vaccine_patient_store_date_is_empty (test_vaccine_patient_tests.TestVaccinePatient)
for testing: store_date is empty
----------------------------------------------------------------------
Traceback (most recent call last):
  File "c:\users\alejandra\desktop\uni\segundo\software_devel\g89.2022.t01.fp\src\main\python\uc3m_care\storage\json_store.py", line 31, in save
    with open(self._FILE_PATH, "w", encoding="utf-8", newline="") as file:
FileNotFoundError: [Errno 2] No such file or directory: 'C:\\Users\\ALEJANDRADesktop/uni/segundo/software_devel/G89.2022.T01.FP/src/JsonFilesstore_patient.json'

The above exception was the direct cause of the following exception:

Traceback (most recent call last):
  File "C:\Users\ALEJANDRA\AppData\Local\Programs\Python\Python38\lib\unittest\case.py", line 60, in testPartExecutor
    yield
  File "C:\Users\ALEJANDRA\AppData\Local\Programs\Python\Python38\lib\unittest\case.py", line 672, in run
    self._callSetUp()
  File "C:\Users\ALEJANDRA\AppData\Local\Programs\Python\Python38\lib\unittest\case.py", line 630, in _callSetUp
    self.setUp()
  File "c:\users\alejandra\desktop\uni\segundo\software_devel\g89.2022.t01.fp\target\venv\build\cpython-3.8.0.final.0\lib\site-packages\freezegun\api.py", line 789, in wrapper
    result = func(*args, **kwargs)
  File "c:\users\alejandra\desktop\uni\segundo\software_devel\g89.2022.t01.fp\src\unittest\python\test_vaccine_patient_tests.py", line 26, in setUp
    my_manager.request_vaccination_id("78924cb0-075a-4099-a3ee-f3b562e805b9",
  File "c:\users\alejandra\desktop\uni\segundo\software_devel\g89.2022.t01.fp\src\main\python\uc3m_care\vaccine_manager.py", line 28, in request_vaccination_id
    my_patient.save_patient()
  File "c:\users\alejandra\desktop\uni\segundo\software_devel\g89.2022.t01.fp\src\main\python\uc3m_care\data\vaccine_patient_register.py", line 121, in save_patient
    patients_store.add_item(self)
  File "c:\users\alejandra\desktop\uni\segundo\software_devel\g89.2022.t01.fp\src\main\python\uc3m_care\storage\patients_json_store.py", line 34, in add_item
    super().add_item(item)
  File "c:\users\alejandra\desktop\uni\segundo\software_devel\g89.2022.t01.fp\src\main\python\uc3m_care\storage\json_store.py", line 40, in add_item
    self.save()
  File "c:\users\alejandra\desktop\uni\segundo\software_devel\g89.2022.t01.fp\src\main\python\uc3m_care\storage\json_store.py", line 34, in save
    raise VaccineManagementException("Wrong file or file path") from ex
uc3m_care.exception.vaccine_management_exception.VaccineManagementException: Wrong file or file path

======================================================================
FAIL [0.013s]: test_Case_NV_02 (test_json_tests.MyTestCase)
Invalid syntax, node 1 duplicated
----------------------------------------------------------------------
Traceback (most recent call last):
  File "C:\Users\ALEJANDRA\AppData\Local\Programs\Python\Python38\lib\unittest\case.py", line 60, in testPartExecutor
    yield
  File "C:\Users\ALEJANDRA\AppData\Local\Programs\Python\Python38\lib\unittest\case.py", line 676, in run
    self._callTestMethod(testMethod)
  File "C:\Users\ALEJANDRA\AppData\Local\Programs\Python\Python38\lib\unittest\case.py", line 633, in _callTestMethod
    method()
  File "c:\users\alejandra\desktop\uni\segundo\software_devel\g89.2022.t01.fp\src\unittest\python\test_json_tests.py", line 61, in test_Case_NV_02
    test_file = self.test_json + "/test_dup_node1"
  File "C:\Users\ALEJANDRA\AppData\Local\Programs\Python\Python38\lib\unittest\case.py", line 227, in __exit__
    self._raiseFailure("{} not raised".format(exc_name))
  File "C:\Users\ALEJANDRA\AppData\Local\Programs\Python\Python38\lib\unittest\case.py", line 164, in _raiseFailure
    raise self.test_case.failureException(msg)
AssertionError: VaccineManagementException not raised

======================================================================
FAIL [0.006s]: test_Case_NV_03 (test_json_tests.MyTestCase)
Invalid syntax, node 1 deleted
----------------------------------------------------------------------
Traceback (most recent call last):
  File "C:\Users\ALEJANDRA\AppData\Local\Programs\Python\Python38\lib\unittest\case.py", line 60, in testPartExecutor
    yield
  File "C:\Users\ALEJANDRA\AppData\Local\Programs\Python\Python38\lib\unittest\case.py", line 676, in run
    self._callTestMethod(testMethod)
  File "C:\Users\ALEJANDRA\AppData\Local\Programs\Python\Python38\lib\unittest\case.py", line 633, in _callTestMethod
    method()
  File "c:\users\alejandra\desktop\uni\segundo\software_devel\g89.2022.t01.fp\src\unittest\python\test_json_tests.py", line 69, in test_Case_NV_03
    test_file = self.test_json + "/test_del_node1"
  File "C:\Users\ALEJANDRA\AppData\Local\Programs\Python\Python38\lib\unittest\case.py", line 227, in __exit__
    self._raiseFailure("{} not raised".format(exc_name))
  File "C:\Users\ALEJANDRA\AppData\Local\Programs\Python\Python38\lib\unittest\case.py", line 164, in _raiseFailure
    raise self.test_case.failureException(msg)
AssertionError: VaccineManagementException not raised

======================================================================
FAIL [0.006s]: test_Case_NV_04 (test_json_tests.MyTestCase)
Invalid syntax, node 3 deleted
----------------------------------------------------------------------
Traceback (most recent call last):
  File "C:\Users\ALEJANDRA\AppData\Local\Programs\Python\Python38\lib\unittest\case.py", line 60, in testPartExecutor
    yield
  File "C:\Users\ALEJANDRA\AppData\Local\Programs\Python\Python38\lib\unittest\case.py", line 676, in run
    self._callTestMethod(testMethod)
  File "C:\Users\ALEJANDRA\AppData\Local\Programs\Python\Python38\lib\unittest\case.py", line 633, in _callTestMethod
    method()
  File "c:\users\alejandra\desktop\uni\segundo\software_devel\g89.2022.t01.fp\src\unittest\python\test_json_tests.py", line 77, in test_Case_NV_04
    test_file = self.test_json + "/test_del_node3"
  File "C:\Users\ALEJANDRA\AppData\Local\Programs\Python\Python38\lib\unittest\case.py", line 227, in __exit__
    self._raiseFailure("{} not raised".format(exc_name))
  File "C:\Users\ALEJANDRA\AppData\Local\Programs\Python\Python38\lib\unittest\case.py", line 164, in _raiseFailure
    raise self.test_case.failureException(msg)
AssertionError: VaccineManagementException not raised

======================================================================
FAIL [0.006s]: test_Case_NV_05 (test_json_tests.MyTestCase)
Invalid syntax, node 3 duplicated
----------------------------------------------------------------------
Traceback (most recent call last):
  File "C:\Users\ALEJANDRA\AppData\Local\Programs\Python\Python38\lib\unittest\case.py", line 60, in testPartExecutor
    yield
  File "C:\Users\ALEJANDRA\AppData\Local\Programs\Python\Python38\lib\unittest\case.py", line 676, in run
    self._callTestMethod(testMethod)
  File "C:\Users\ALEJANDRA\AppData\Local\Programs\Python\Python38\lib\unittest\case.py", line 633, in _callTestMethod
    method()
  File "c:\users\alejandra\desktop\uni\segundo\software_devel\g89.2022.t01.fp\src\unittest\python\test_json_tests.py", line 85, in test_Case_NV_05
    test_file = self.test_json + "/test_dup_node3.json"
  File "C:\Users\ALEJANDRA\AppData\Local\Programs\Python\Python38\lib\unittest\case.py", line 227, in __exit__
    self._raiseFailure("{} not raised".format(exc_name))
  File "C:\Users\ALEJANDRA\AppData\Local\Programs\Python\Python38\lib\unittest\case.py", line 164, in _raiseFailure
    raise self.test_case.failureException(msg)
AssertionError: VaccineManagementException not raised

======================================================================
FAIL [0.007s]: test_Case_NV_06 (test_json_tests.MyTestCase)
Invalid syntax, node 5 deleted
----------------------------------------------------------------------
Traceback (most recent call last):
  File "C:\Users\ALEJANDRA\AppData\Local\Programs\Python\Python38\lib\unittest\case.py", line 60, in testPartExecutor
    yield
  File "C:\Users\ALEJANDRA\AppData\Local\Programs\Python\Python38\lib\unittest\case.py", line 676, in run
    self._callTestMethod(testMethod)
  File "C:\Users\ALEJANDRA\AppData\Local\Programs\Python\Python38\lib\unittest\case.py", line 633, in _callTestMethod
    method()
  File "c:\users\alejandra\desktop\uni\segundo\software_devel\g89.2022.t01.fp\src\unittest\python\test_json_tests.py", line 93, in test_Case_NV_06
    test_file = self.test_json + "/test_del_node5.json"
  File "C:\Users\ALEJANDRA\AppData\Local\Programs\Python\Python38\lib\unittest\case.py", line 227, in __exit__
    self._raiseFailure("{} not raised".format(exc_name))
  File "C:\Users\ALEJANDRA\AppData\Local\Programs\Python\Python38\lib\unittest\case.py", line 164, in _raiseFailure
    raise self.test_case.failureException(msg)
AssertionError: VaccineManagementException not raised

======================================================================
FAIL [0.005s]: test_Case_NV_07 (test_json_tests.MyTestCase)
Invalid syntax, node 5 duplicated
----------------------------------------------------------------------
Traceback (most recent call last):
  File "C:\Users\ALEJANDRA\AppData\Local\Programs\Python\Python38\lib\unittest\case.py", line 60, in testPartExecutor
    yield
  File "C:\Users\ALEJANDRA\AppData\Local\Programs\Python\Python38\lib\unittest\case.py", line 676, in run
    self._callTestMethod(testMethod)
  File "C:\Users\ALEJANDRA\AppData\Local\Programs\Python\Python38\lib\unittest\case.py", line 633, in _callTestMethod
    method()
  File "c:\users\alejandra\desktop\uni\segundo\software_devel\g89.2022.t01.fp\src\unittest\python\test_json_tests.py", line 101, in test_Case_NV_07
    test_file = self.test_json + "/test_dup_node2.json"
  File "C:\Users\ALEJANDRA\AppData\Local\Programs\Python\Python38\lib\unittest\case.py", line 227, in __exit__
    self._raiseFailure("{} not raised".format(exc_name))
  File "C:\Users\ALEJANDRA\AppData\Local\Programs\Python\Python38\lib\unittest\case.py", line 164, in _raiseFailure
    raise self.test_case.failureException(msg)
AssertionError: VaccineManagementException not raised

======================================================================
FAIL [0.006s]: test_Case_NV_08 (test_json_tests.MyTestCase)
Invalid syntax, node 5 modified
----------------------------------------------------------------------
Traceback (most recent call last):
  File "C:\Users\ALEJANDRA\AppData\Local\Programs\Python\Python38\lib\unittest\case.py", line 60, in testPartExecutor
    yield
  File "C:\Users\ALEJANDRA\AppData\Local\Programs\Python\Python38\lib\unittest\case.py", line 676, in run
    self._callTestMethod(testMethod)
  File "C:\Users\ALEJANDRA\AppData\Local\Programs\Python\Python38\lib\unittest\case.py", line 633, in _callTestMethod
    method()
  File "c:\users\alejandra\desktop\uni\segundo\software_devel\g89.2022.t01.fp\src\unittest\python\test_json_tests.py", line 109, in test_Case_NV_08
    test_file = self.test_json + "/test_mod_node2.json"
  File "C:\Users\ALEJANDRA\AppData\Local\Programs\Python\Python38\lib\unittest\case.py", line 227, in __exit__
    self._raiseFailure("{} not raised".format(exc_name))
  File "C:\Users\ALEJANDRA\AppData\Local\Programs\Python\Python38\lib\unittest\case.py", line 164, in _raiseFailure
    raise self.test_case.failureException(msg)
AssertionError: VaccineManagementException not raised

======================================================================
FAIL [0.006s]: test_Case_NV_09 (test_json_tests.MyTestCase)
Invalid syntax, node 6 deleted
----------------------------------------------------------------------
Traceback (most recent call last):
  File "C:\Users\ALEJANDRA\AppData\Local\Programs\Python\Python38\lib\unittest\case.py", line 60, in testPartExecutor
    yield
  File "C:\Users\ALEJANDRA\AppData\Local\Programs\Python\Python38\lib\unittest\case.py", line 676, in run
    self._callTestMethod(testMethod)
  File "C:\Users\ALEJANDRA\AppData\Local\Programs\Python\Python38\lib\unittest\case.py", line 633, in _callTestMethod
    method()
  File "c:\users\alejandra\desktop\uni\segundo\software_devel\g89.2022.t01.fp\src\unittest\python\test_json_tests.py", line 117, in test_Case_NV_09
    test_file = self.test_json + "/test_del_node6.json"
  File "C:\Users\ALEJANDRA\AppData\Local\Programs\Python\Python38\lib\unittest\case.py", line 227, in __exit__
    self._raiseFailure("{} not raised".format(exc_name))
  File "C:\Users\ALEJANDRA\AppData\Local\Programs\Python\Python38\lib\unittest\case.py", line 164, in _raiseFailure
    raise self.test_case.failureException(msg)
AssertionError: VaccineManagementException not raised

======================================================================
FAIL [0.005s]: test_Case_NV_10 (test_json_tests.MyTestCase)
Invalid syntax, node 6 duplicated
----------------------------------------------------------------------
Traceback (most recent call last):
  File "C:\Users\ALEJANDRA\AppData\Local\Programs\Python\Python38\lib\unittest\case.py", line 60, in testPartExecutor
    yield
  File "C:\Users\ALEJANDRA\AppData\Local\Programs\Python\Python38\lib\unittest\case.py", line 676, in run
    self._callTestMethod(testMethod)
  File "C:\Users\ALEJANDRA\AppData\Local\Programs\Python\Python38\lib\unittest\case.py", line 633, in _callTestMethod
    method()
  File "c:\users\alejandra\desktop\uni\segundo\software_devel\g89.2022.t01.fp\src\unittest\python\test_json_tests.py", line 125, in test_Case_NV_10
    test_file = self.test_json + "/test_dup_node6.json"
  File "C:\Users\ALEJANDRA\AppData\Local\Programs\Python\Python38\lib\unittest\case.py", line 227, in __exit__
    self._raiseFailure("{} not raised".format(exc_name))
  File "C:\Users\ALEJANDRA\AppData\Local\Programs\Python\Python38\lib\unittest\case.py", line 164, in _raiseFailure
    raise self.test_case.failureException(msg)
AssertionError: VaccineManagementException not raised

======================================================================
FAIL [0.006s]: test_Case_NV_11 (test_json_tests.MyTestCase)
Invalid syntax, node 11 deleted
----------------------------------------------------------------------
Traceback (most recent call last):
  File "C:\Users\ALEJANDRA\AppData\Local\Programs\Python\Python38\lib\unittest\case.py", line 60, in testPartExecutor
    yield
  File "C:\Users\ALEJANDRA\AppData\Local\Programs\Python\Python38\lib\unittest\case.py", line 676, in run
    self._callTestMethod(testMethod)
  File "C:\Users\ALEJANDRA\AppData\Local\Programs\Python\Python38\lib\unittest\case.py", line 633, in _callTestMethod
    method()
  File "c:\users\alejandra\desktop\uni\segundo\software_devel\g89.2022.t01.fp\src\unittest\python\test_json_tests.py", line 133, in test_Case_NV_11
    test_file = self.test_json + "/test_del_node11.json"
  File "C:\Users\ALEJANDRA\AppData\Local\Programs\Python\Python38\lib\unittest\case.py", line 227, in __exit__
    self._raiseFailure("{} not raised".format(exc_name))
  File "C:\Users\ALEJANDRA\AppData\Local\Programs\Python\Python38\lib\unittest\case.py", line 164, in _raiseFailure
    raise self.test_case.failureException(msg)
AssertionError: VaccineManagementException not raised

======================================================================
FAIL [0.006s]: test_Case_NV_12 (test_json_tests.MyTestCase)
Invalid syntax, node 11 duplicated
----------------------------------------------------------------------
Traceback (most recent call last):
  File "C:\Users\ALEJANDRA\AppData\Local\Programs\Python\Python38\lib\unittest\case.py", line 60, in testPartExecutor
    yield
  File "C:\Users\ALEJANDRA\AppData\Local\Programs\Python\Python38\lib\unittest\case.py", line 676, in run
    self._callTestMethod(testMethod)
  File "C:\Users\ALEJANDRA\AppData\Local\Programs\Python\Python38\lib\unittest\case.py", line 633, in _callTestMethod
    method()
  File "c:\users\alejandra\desktop\uni\segundo\software_devel\g89.2022.t01.fp\src\unittest\python\test_json_tests.py", line 141, in test_Case_NV_12
    test_file = self.test_json + "/test_dup_node4.json"
  File "C:\Users\ALEJANDRA\AppData\Local\Programs\Python\Python38\lib\unittest\case.py", line 227, in __exit__
    self._raiseFailure("{} not raised".format(exc_name))
  File "C:\Users\ALEJANDRA\AppData\Local\Programs\Python\Python38\lib\unittest\case.py", line 164, in _raiseFailure
    raise self.test_case.failureException(msg)
AssertionError: VaccineManagementException not raised

======================================================================
FAIL [0.006s]: test_Case_NV_13 (test_json_tests.MyTestCase)
Invalid syntax, node 11 modified
----------------------------------------------------------------------
Traceback (most recent call last):
  File "C:\Users\ALEJANDRA\AppData\Local\Programs\Python\Python38\lib\unittest\case.py", line 60, in testPartExecutor
    yield
  File "C:\Users\ALEJANDRA\AppData\Local\Programs\Python\Python38\lib\unittest\case.py", line 676, in run
    self._callTestMethod(testMethod)
  File "C:\Users\ALEJANDRA\AppData\Local\Programs\Python\Python38\lib\unittest\case.py", line 633, in _callTestMethod
    method()
  File "c:\users\alejandra\desktop\uni\segundo\software_devel\g89.2022.t01.fp\src\unittest\python\test_json_tests.py", line 149, in test_Case_NV_13
    test_file = self.test_json + "/test_mod_node4.json"
  File "C:\Users\ALEJANDRA\AppData\Local\Programs\Python\Python38\lib\unittest\case.py", line 227, in __exit__
    self._raiseFailure("{} not raised".format(exc_name))
  File "C:\Users\ALEJANDRA\AppData\Local\Programs\Python\Python38\lib\unittest\case.py", line 164, in _raiseFailure
    raise self.test_case.failureException(msg)
AssertionError: VaccineManagementException not raised

======================================================================
FAIL [0.007s]: test_Case_NV_14 (test_json_tests.MyTestCase)
Invalid syntax, node 12 deleted
----------------------------------------------------------------------
Traceback (most recent call last):
  File "C:\Users\ALEJANDRA\AppData\Local\Programs\Python\Python38\lib\unittest\case.py", line 60, in testPartExecutor
    yield
  File "C:\Users\ALEJANDRA\AppData\Local\Programs\Python\Python38\lib\unittest\case.py", line 676, in run
    self._callTestMethod(testMethod)
  File "C:\Users\ALEJANDRA\AppData\Local\Programs\Python\Python38\lib\unittest\case.py", line 633, in _callTestMethod
    method()
  File "c:\users\alejandra\desktop\uni\segundo\software_devel\g89.2022.t01.fp\src\unittest\python\test_json_tests.py", line 157, in test_Case_NV_14
    test_file = self.test_json + "/test_del_node12.json"
  File "C:\Users\ALEJANDRA\AppData\Local\Programs\Python\Python38\lib\unittest\case.py", line 227, in __exit__
    self._raiseFailure("{} not raised".format(exc_name))
  File "C:\Users\ALEJANDRA\AppData\Local\Programs\Python\Python38\lib\unittest\case.py", line 164, in _raiseFailure
    raise self.test_case.failureException(msg)
AssertionError: VaccineManagementException not raised

======================================================================
FAIL [0.006s]: test_Case_NV_15 (test_json_tests.MyTestCase)
Invalid syntax, node 12 duplicated
----------------------------------------------------------------------
Traceback (most recent call last):
  File "C:\Users\ALEJANDRA\AppData\Local\Programs\Python\Python38\lib\unittest\case.py", line 60, in testPartExecutor
    yield
  File "C:\Users\ALEJANDRA\AppData\Local\Programs\Python\Python38\lib\unittest\case.py", line 676, in run
    self._callTestMethod(testMethod)
  File "C:\Users\ALEJANDRA\AppData\Local\Programs\Python\Python38\lib\unittest\case.py", line 633, in _callTestMethod
    method()
  File "c:\users\alejandra\desktop\uni\segundo\software_devel\g89.2022.t01.fp\src\unittest\python\test_json_tests.py", line 165, in test_Case_NV_15
    test_file = self.test_json + "/test_dup_node12.json"
  File "C:\Users\ALEJANDRA\AppData\Local\Programs\Python\Python38\lib\unittest\case.py", line 227, in __exit__
    self._raiseFailure("{} not raised".format(exc_name))
  File "C:\Users\ALEJANDRA\AppData\Local\Programs\Python\Python38\lib\unittest\case.py", line 164, in _raiseFailure
    raise self.test_case.failureException(msg)
AssertionError: VaccineManagementException not raised

======================================================================
FAIL [0.006s]: test_Case_NV_16 (test_json_tests.MyTestCase)
Invalid syntax, node 14 deleted
----------------------------------------------------------------------
Traceback (most recent call last):
  File "C:\Users\ALEJANDRA\AppData\Local\Programs\Python\Python38\lib\unittest\case.py", line 60, in testPartExecutor
    yield
  File "C:\Users\ALEJANDRA\AppData\Local\Programs\Python\Python38\lib\unittest\case.py", line 676, in run
    self._callTestMethod(testMethod)
  File "C:\Users\ALEJANDRA\AppData\Local\Programs\Python\Python38\lib\unittest\case.py", line 633, in _callTestMethod
    method()
  File "c:\users\alejandra\desktop\uni\segundo\software_devel\g89.2022.t01.fp\src\unittest\python\test_json_tests.py", line 173, in test_Case_NV_16
    test_file = self.test_json + "/test_del_node14.json"
  File "C:\Users\ALEJANDRA\AppData\Local\Programs\Python\Python38\lib\unittest\case.py", line 227, in __exit__
    self._raiseFailure("{} not raised".format(exc_name))
  File "C:\Users\ALEJANDRA\AppData\Local\Programs\Python\Python38\lib\unittest\case.py", line 164, in _raiseFailure
    raise self.test_case.failureException(msg)
AssertionError: VaccineManagementException not raised

======================================================================
FAIL [0.006s]: test_Case_NV_17 (test_json_tests.MyTestCase)
Invalid syntax, node 14 duplicated
----------------------------------------------------------------------
Traceback (most recent call last):
  File "C:\Users\ALEJANDRA\AppData\Local\Programs\Python\Python38\lib\unittest\case.py", line 60, in testPartExecutor
    yield
  File "C:\Users\ALEJANDRA\AppData\Local\Programs\Python\Python38\lib\unittest\case.py", line 676, in run
    self._callTestMethod(testMethod)
  File "C:\Users\ALEJANDRA\AppData\Local\Programs\Python\Python38\lib\unittest\case.py", line 633, in _callTestMethod
    method()
  File "c:\users\alejandra\desktop\uni\segundo\software_devel\g89.2022.t01.fp\src\unittest\python\test_json_tests.py", line 181, in test_Case_NV_17
    test_file = self.test_json + "/test_dup_node14.json"
  File "C:\Users\ALEJANDRA\AppData\Local\Programs\Python\Python38\lib\unittest\case.py", line 227, in __exit__
    self._raiseFailure("{} not raised".format(exc_name))
  File "C:\Users\ALEJANDRA\AppData\Local\Programs\Python\Python38\lib\unittest\case.py", line 164, in _raiseFailure
    raise self.test_case.failureException(msg)
AssertionError: VaccineManagementException not raised

======================================================================
FAIL [0.006s]: test_Case_NV_18 (test_json_tests.MyTestCase)
Invalid syntax, node 16 deleted
----------------------------------------------------------------------
Traceback (most recent call last):
  File "C:\Users\ALEJANDRA\AppData\Local\Programs\Python\Python38\lib\unittest\case.py", line 60, in testPartExecutor
    yield
  File "C:\Users\ALEJANDRA\AppData\Local\Programs\Python\Python38\lib\unittest\case.py", line 676, in run
    self._callTestMethod(testMethod)
  File "C:\Users\ALEJANDRA\AppData\Local\Programs\Python\Python38\lib\unittest\case.py", line 633, in _callTestMethod
    method()
  File "c:\users\alejandra\desktop\uni\segundo\software_devel\g89.2022.t01.fp\src\unittest\python\test_json_tests.py", line 189, in test_Case_NV_18
    test_file = self.test_json + "/test_del_node16.json"
  File "C:\Users\ALEJANDRA\AppData\Local\Programs\Python\Python38\lib\unittest\case.py", line 227, in __exit__
    self._raiseFailure("{} not raised".format(exc_name))
  File "C:\Users\ALEJANDRA\AppData\Local\Programs\Python\Python38\lib\unittest\case.py", line 164, in _raiseFailure
    raise self.test_case.failureException(msg)
AssertionError: VaccineManagementException not raised

======================================================================
FAIL [0.005s]: test_Case_NV_19 (test_json_tests.MyTestCase)
Invalid syntax, node 16 duplicated
----------------------------------------------------------------------
Traceback (most recent call last):
  File "C:\Users\ALEJANDRA\AppData\Local\Programs\Python\Python38\lib\unittest\case.py", line 60, in testPartExecutor
    yield
  File "C:\Users\ALEJANDRA\AppData\Local\Programs\Python\Python38\lib\unittest\case.py", line 676, in run
    self._callTestMethod(testMethod)
  File "C:\Users\ALEJANDRA\AppData\Local\Programs\Python\Python38\lib\unittest\case.py", line 633, in _callTestMethod
    method()
  File "c:\users\alejandra\desktop\uni\segundo\software_devel\g89.2022.t01.fp\src\unittest\python\test_json_tests.py", line 197, in test_Case_NV_19
    test_file = self.test_json + "/test_dup_node16.json"
  File "C:\Users\ALEJANDRA\AppData\Local\Programs\Python\Python38\lib\unittest\case.py", line 227, in __exit__
    self._raiseFailure("{} not raised".format(exc_name))
  File "C:\Users\ALEJANDRA\AppData\Local\Programs\Python\Python38\lib\unittest\case.py", line 164, in _raiseFailure
    raise self.test_case.failureException(msg)
AssertionError: VaccineManagementException not raised

======================================================================
FAIL [0.007s]: test_Case_NV_20 (test_json_tests.MyTestCase)
Invalid syntax, node 18 deleted
----------------------------------------------------------------------
Traceback (most recent call last):
  File "C:\Users\ALEJANDRA\AppData\Local\Programs\Python\Python38\lib\unittest\case.py", line 60, in testPartExecutor
    yield
  File "C:\Users\ALEJANDRA\AppData\Local\Programs\Python\Python38\lib\unittest\case.py", line 676, in run
    self._callTestMethod(testMethod)
  File "C:\Users\ALEJANDRA\AppData\Local\Programs\Python\Python38\lib\unittest\case.py", line 633, in _callTestMethod
    method()
  File "c:\users\alejandra\desktop\uni\segundo\software_devel\g89.2022.t01.fp\src\unittest\python\test_json_tests.py", line 205, in test_Case_NV_20
    test_file = self.test_json + "/test_del_node18.json"
  File "C:\Users\ALEJANDRA\AppData\Local\Programs\Python\Python38\lib\unittest\case.py", line 227, in __exit__
    self._raiseFailure("{} not raised".format(exc_name))
  File "C:\Users\ALEJANDRA\AppData\Local\Programs\Python\Python38\lib\unittest\case.py", line 164, in _raiseFailure
    raise self.test_case.failureException(msg)
AssertionError: VaccineManagementException not raised

======================================================================
FAIL [0.007s]: test_Case_NV_21 (test_json_tests.MyTestCase)
Invalid syntax, node 18 duplicated
----------------------------------------------------------------------
Traceback (most recent call last):
  File "C:\Users\ALEJANDRA\AppData\Local\Programs\Python\Python38\lib\unittest\case.py", line 60, in testPartExecutor
    yield
  File "C:\Users\ALEJANDRA\AppData\Local\Programs\Python\Python38\lib\unittest\case.py", line 676, in run
    self._callTestMethod(testMethod)
  File "C:\Users\ALEJANDRA\AppData\Local\Programs\Python\Python38\lib\unittest\case.py", line 633, in _callTestMethod
    method()
  File "c:\users\alejandra\desktop\uni\segundo\software_devel\g89.2022.t01.fp\src\unittest\python\test_json_tests.py", line 213, in test_Case_NV_21
    test_file = self.test_json + "/test_dup_node18.json"
  File "C:\Users\ALEJANDRA\AppData\Local\Programs\Python\Python38\lib\unittest\case.py", line 227, in __exit__
    self._raiseFailure("{} not raised".format(exc_name))
  File "C:\Users\ALEJANDRA\AppData\Local\Programs\Python\Python38\lib\unittest\case.py", line 164, in _raiseFailure
    raise self.test_case.failureException(msg)
AssertionError: VaccineManagementException not raised

======================================================================
FAIL [0.006s]: test_Case_NV_22 (test_json_tests.MyTestCase)
Invalid syntax, node 20 deleted
----------------------------------------------------------------------
Traceback (most recent call last):
  File "C:\Users\ALEJANDRA\AppData\Local\Programs\Python\Python38\lib\unittest\case.py", line 60, in testPartExecutor
    yield
  File "C:\Users\ALEJANDRA\AppData\Local\Programs\Python\Python38\lib\unittest\case.py", line 676, in run
    self._callTestMethod(testMethod)
  File "C:\Users\ALEJANDRA\AppData\Local\Programs\Python\Python38\lib\unittest\case.py", line 633, in _callTestMethod
    method()
  File "c:\users\alejandra\desktop\uni\segundo\software_devel\g89.2022.t01.fp\src\unittest\python\test_json_tests.py", line 221, in test_Case_NV_22
    test_file = self.test_json + "/test_del_node20.json"
  File "C:\Users\ALEJANDRA\AppData\Local\Programs\Python\Python38\lib\unittest\case.py", line 227, in __exit__
    self._raiseFailure("{} not raised".format(exc_name))
  File "C:\Users\ALEJANDRA\AppData\Local\Programs\Python\Python38\lib\unittest\case.py", line 164, in _raiseFailure
    raise self.test_case.failureException(msg)
AssertionError: VaccineManagementException not raised

======================================================================
FAIL [0.006s]: test_Case_NV_23 (test_json_tests.MyTestCase)
Invalid syntax, node 20 duplicated
----------------------------------------------------------------------
Traceback (most recent call last):
  File "C:\Users\ALEJANDRA\AppData\Local\Programs\Python\Python38\lib\unittest\case.py", line 60, in testPartExecutor
    yield
  File "C:\Users\ALEJANDRA\AppData\Local\Programs\Python\Python38\lib\unittest\case.py", line 676, in run
    self._callTestMethod(testMethod)
  File "C:\Users\ALEJANDRA\AppData\Local\Programs\Python\Python38\lib\unittest\case.py", line 633, in _callTestMethod
    method()
  File "c:\users\alejandra\desktop\uni\segundo\software_devel\g89.2022.t01.fp\src\unittest\python\test_json_tests.py", line 229, in test_Case_NV_23
    test_file = self.test_json + "/test_dup_node20.json"
  File "C:\Users\ALEJANDRA\AppData\Local\Programs\Python\Python38\lib\unittest\case.py", line 227, in __exit__
    self._raiseFailure("{} not raised".format(exc_name))
  File "C:\Users\ALEJANDRA\AppData\Local\Programs\Python\Python38\lib\unittest\case.py", line 164, in _raiseFailure
    raise self.test_case.failureException(msg)
AssertionError: VaccineManagementException not raised

======================================================================
FAIL [0.006s]: test_Case_NV_24 (test_json_tests.MyTestCase)
Invalid syntax, node 22 deleted
----------------------------------------------------------------------
Traceback (most recent call last):
  File "C:\Users\ALEJANDRA\AppData\Local\Programs\Python\Python38\lib\unittest\case.py", line 60, in testPartExecutor
    yield
  File "C:\Users\ALEJANDRA\AppData\Local\Programs\Python\Python38\lib\unittest\case.py", line 676, in run
    self._callTestMethod(testMethod)
  File "C:\Users\ALEJANDRA\AppData\Local\Programs\Python\Python38\lib\unittest\case.py", line 633, in _callTestMethod
    method()
  File "c:\users\alejandra\desktop\uni\segundo\software_devel\g89.2022.t01.fp\src\unittest\python\test_json_tests.py", line 237, in test_Case_NV_24
    test_file = self.test_json + "/test_del_node22.json"
  File "C:\Users\ALEJANDRA\AppData\Local\Programs\Python\Python38\lib\unittest\case.py", line 227, in __exit__
    self._raiseFailure("{} not raised".format(exc_name))
  File "C:\Users\ALEJANDRA\AppData\Local\Programs\Python\Python38\lib\unittest\case.py", line 164, in _raiseFailure
    raise self.test_case.failureException(msg)
AssertionError: VaccineManagementException not raised

======================================================================
FAIL [0.005s]: test_Case_NV_25 (test_json_tests.MyTestCase)
Invalid syntax, node 22 duplicated
----------------------------------------------------------------------
Traceback (most recent call last):
  File "C:\Users\ALEJANDRA\AppData\Local\Programs\Python\Python38\lib\unittest\case.py", line 60, in testPartExecutor
    yield
  File "C:\Users\ALEJANDRA\AppData\Local\Programs\Python\Python38\lib\unittest\case.py", line 676, in run
    self._callTestMethod(testMethod)
  File "C:\Users\ALEJANDRA\AppData\Local\Programs\Python\Python38\lib\unittest\case.py", line 633, in _callTestMethod
    method()
  File "c:\users\alejandra\desktop\uni\segundo\software_devel\g89.2022.t01.fp\src\unittest\python\test_json_tests.py", line 245, in test_Case_NV_25
    test_file = self.test_json + "/test_dup_node22.json"
  File "C:\Users\ALEJANDRA\AppData\Local\Programs\Python\Python38\lib\unittest\case.py", line 227, in __exit__
    self._raiseFailure("{} not raised".format(exc_name))
  File "C:\Users\ALEJANDRA\AppData\Local\Programs\Python\Python38\lib\unittest\case.py", line 164, in _raiseFailure
    raise self.test_case.failureException(msg)
AssertionError: VaccineManagementException not raised

======================================================================
FAIL [0.006s]: test_Case_NV_26 (test_json_tests.MyTestCase)
Invalid syntax, node quotation deleted
----------------------------------------------------------------------
Traceback (most recent call last):
  File "C:\Users\ALEJANDRA\AppData\Local\Programs\Python\Python38\lib\unittest\case.py", line 60, in testPartExecutor
    yield
  File "C:\Users\ALEJANDRA\AppData\Local\Programs\Python\Python38\lib\unittest\case.py", line 676, in run
    self._callTestMethod(testMethod)
  File "C:\Users\ALEJANDRA\AppData\Local\Programs\Python\Python38\lib\unittest\case.py", line 633, in _callTestMethod
    method()
  File "c:\users\alejandra\desktop\uni\segundo\software_devel\g89.2022.t01.fp\src\unittest\python\test_json_tests.py", line 253, in test_Case_NV_26
    test_file = self.test_json + "/test_del_quotation.json"
  File "C:\Users\ALEJANDRA\AppData\Local\Programs\Python\Python38\lib\unittest\case.py", line 227, in __exit__
    self._raiseFailure("{} not raised".format(exc_name))
  File "C:\Users\ALEJANDRA\AppData\Local\Programs\Python\Python38\lib\unittest\case.py", line 164, in _raiseFailure
    raise self.test_case.failureException(msg)
AssertionError: VaccineManagementException not raised

======================================================================
FAIL [0.007s]: test_Case_NV_27 (test_json_tests.MyTestCase)
Invalid syntax, node quotation duplicated
----------------------------------------------------------------------
Traceback (most recent call last):
  File "C:\Users\ALEJANDRA\AppData\Local\Programs\Python\Python38\lib\unittest\case.py", line 60, in testPartExecutor
    yield
  File "C:\Users\ALEJANDRA\AppData\Local\Programs\Python\Python38\lib\unittest\case.py", line 676, in run
    self._callTestMethod(testMethod)
  File "C:\Users\ALEJANDRA\AppData\Local\Programs\Python\Python38\lib\unittest\case.py", line 633, in _callTestMethod
    method()
  File "c:\users\alejandra\desktop\uni\segundo\software_devel\g89.2022.t01.fp\src\unittest\python\test_json_tests.py", line 261, in test_Case_NV_27
    test_file = self.test_json + "/test_dup_quotation.json"
  File "C:\Users\ALEJANDRA\AppData\Local\Programs\Python\Python38\lib\unittest\case.py", line 227, in __exit__
    self._raiseFailure("{} not raised".format(exc_name))
  File "C:\Users\ALEJANDRA\AppData\Local\Programs\Python\Python38\lib\unittest\case.py", line 164, in _raiseFailure
    raise self.test_case.failureException(msg)
AssertionError: VaccineManagementException not raised

======================================================================
FAIL [0.007s]: test_Case_NV_28 (test_json_tests.MyTestCase)
Invalid syntax, node quotation modified
----------------------------------------------------------------------
Traceback (most recent call last):
  File "C:\Users\ALEJANDRA\AppData\Local\Programs\Python\Python38\lib\unittest\case.py", line 60, in testPartExecutor
    yield
  File "C:\Users\ALEJANDRA\AppData\Local\Programs\Python\Python38\lib\unittest\case.py", line 676, in run
    self._callTestMethod(testMethod)
  File "C:\Users\ALEJANDRA\AppData\Local\Programs\Python\Python38\lib\unittest\case.py", line 633, in _callTestMethod
    method()
  File "c:\users\alejandra\desktop\uni\segundo\software_devel\g89.2022.t01.fp\src\unittest\python\test_json_tests.py", line 269, in test_Case_NV_28
    test_file = self.test_json + "/test_mod_quotation.json"
  File "C:\Users\ALEJANDRA\AppData\Local\Programs\Python\Python38\lib\unittest\case.py", line 227, in __exit__
    self._raiseFailure("{} not raised".format(exc_name))
  File "C:\Users\ALEJANDRA\AppData\Local\Programs\Python\Python38\lib\unittest\case.py", line 164, in _raiseFailure
    raise self.test_case.failureException(msg)
AssertionError: VaccineManagementException not raised

======================================================================
FAIL [0.005s]: test_Case_NV_29 (test_json_tests.MyTestCase)
Invalid syntax, node separator deleted
----------------------------------------------------------------------
Traceback (most recent call last):
  File "C:\Users\ALEJANDRA\AppData\Local\Programs\Python\Python38\lib\unittest\case.py", line 60, in testPartExecutor
    yield
  File "C:\Users\ALEJANDRA\AppData\Local\Programs\Python\Python38\lib\unittest\case.py", line 676, in run
    self._callTestMethod(testMethod)
  File "C:\Users\ALEJANDRA\AppData\Local\Programs\Python\Python38\lib\unittest\case.py", line 633, in _callTestMethod
    method()
  File "c:\users\alejandra\desktop\uni\segundo\software_devel\g89.2022.t01.fp\src\unittest\python\test_json_tests.py", line 277, in test_Case_NV_29
    test_file = self.test_json + "/test_del_separator.json"
  File "C:\Users\ALEJANDRA\AppData\Local\Programs\Python\Python38\lib\unittest\case.py", line 227, in __exit__
    self._raiseFailure("{} not raised".format(exc_name))
  File "C:\Users\ALEJANDRA\AppData\Local\Programs\Python\Python38\lib\unittest\case.py", line 164, in _raiseFailure
    raise self.test_case.failureException(msg)
AssertionError: VaccineManagementException not raised

======================================================================
FAIL [0.006s]: test_Case_NV_30 (test_json_tests.MyTestCase)
Invalid syntax, node separator duplicated
----------------------------------------------------------------------
Traceback (most recent call last):
  File "C:\Users\ALEJANDRA\AppData\Local\Programs\Python\Python38\lib\unittest\case.py", line 60, in testPartExecutor
    yield
  File "C:\Users\ALEJANDRA\AppData\Local\Programs\Python\Python38\lib\unittest\case.py", line 676, in run
    self._callTestMethod(testMethod)
  File "C:\Users\ALEJANDRA\AppData\Local\Programs\Python\Python38\lib\unittest\case.py", line 633, in _callTestMethod
    method()
  File "c:\users\alejandra\desktop\uni\segundo\software_devel\g89.2022.t01.fp\src\unittest\python\test_json_tests.py", line 285, in test_Case_NV_30
    test_file = self.test_json + "/test_dup_separator.json"
  File "C:\Users\ALEJANDRA\AppData\Local\Programs\Python\Python38\lib\unittest\case.py", line 227, in __exit__
    self._raiseFailure("{} not raised".format(exc_name))
  File "C:\Users\ALEJANDRA\AppData\Local\Programs\Python\Python38\lib\unittest\case.py", line 164, in _raiseFailure
    raise self.test_case.failureException(msg)
AssertionError: VaccineManagementException not raised

======================================================================
FAIL [0.006s]: test_Case_NV_31 (test_json_tests.MyTestCase)
Invalid syntax, node separator modified
----------------------------------------------------------------------
Traceback (most recent call last):
  File "C:\Users\ALEJANDRA\AppData\Local\Programs\Python\Python38\lib\unittest\case.py", line 60, in testPartExecutor
    yield
  File "C:\Users\ALEJANDRA\AppData\Local\Programs\Python\Python38\lib\unittest\case.py", line 676, in run
    self._callTestMethod(testMethod)
  File "C:\Users\ALEJANDRA\AppData\Local\Programs\Python\Python38\lib\unittest\case.py", line 633, in _callTestMethod
    method()
  File "c:\users\alejandra\desktop\uni\segundo\software_devel\g89.2022.t01.fp\src\unittest\python\test_json_tests.py", line 293, in test_Case_NV_31
    test_file = self.test_json + "/test_mod_separator.json"
  File "C:\Users\ALEJANDRA\AppData\Local\Programs\Python\Python38\lib\unittest\case.py", line 227, in __exit__
    self._raiseFailure("{} not raised".format(exc_name))
  File "C:\Users\ALEJANDRA\AppData\Local\Programs\Python\Python38\lib\unittest\case.py", line 164, in _raiseFailure
    raise self.test_case.failureException(msg)
AssertionError: VaccineManagementException not raised

======================================================================
FAIL [0.006s]: test_Case_NV_32 (test_json_tests.MyTestCase)
Invalid syntax, node separator2 deleted
----------------------------------------------------------------------
Traceback (most recent call last):
  File "C:\Users\ALEJANDRA\AppData\Local\Programs\Python\Python38\lib\unittest\case.py", line 60, in testPartExecutor
    yield
  File "C:\Users\ALEJANDRA\AppData\Local\Programs\Python\Python38\lib\unittest\case.py", line 676, in run
    self._callTestMethod(testMethod)
  File "C:\Users\ALEJANDRA\AppData\Local\Programs\Python\Python38\lib\unittest\case.py", line 633, in _callTestMethod
    method()
  File "c:\users\alejandra\desktop\uni\segundo\software_devel\g89.2022.t01.fp\src\unittest\python\test_json_tests.py", line 301, in test_Case_NV_32
    test_file = self.test_json + "/test_del_separator2.json"
  File "C:\Users\ALEJANDRA\AppData\Local\Programs\Python\Python38\lib\unittest\case.py", line 227, in __exit__
    self._raiseFailure("{} not raised".format(exc_name))
  File "C:\Users\ALEJANDRA\AppData\Local\Programs\Python\Python38\lib\unittest\case.py", line 164, in _raiseFailure
    raise self.test_case.failureException(msg)
AssertionError: VaccineManagementException not raised

======================================================================
FAIL [0.006s]: test_Case_NV_33 (test_json_tests.MyTestCase)
Invalid syntax, node separator2 duplicated
----------------------------------------------------------------------
Traceback (most recent call last):
  File "C:\Users\ALEJANDRA\AppData\Local\Programs\Python\Python38\lib\unittest\case.py", line 60, in testPartExecutor
    yield
  File "C:\Users\ALEJANDRA\AppData\Local\Programs\Python\Python38\lib\unittest\case.py", line 676, in run
    self._callTestMethod(testMethod)
  File "C:\Users\ALEJANDRA\AppData\Local\Programs\Python\Python38\lib\unittest\case.py", line 633, in _callTestMethod
    method()
  File "c:\users\alejandra\desktop\uni\segundo\software_devel\g89.2022.t01.fp\src\unittest\python\test_json_tests.py", line 309, in test_Case_NV_33
    test_file = self.test_json + "/test_dup_separator2.json"
  File "C:\Users\ALEJANDRA\AppData\Local\Programs\Python\Python38\lib\unittest\case.py", line 227, in __exit__
    self._raiseFailure("{} not raised".format(exc_name))
  File "C:\Users\ALEJANDRA\AppData\Local\Programs\Python\Python38\lib\unittest\case.py", line 164, in _raiseFailure
    raise self.test_case.failureException(msg)
AssertionError: VaccineManagementException not raised

======================================================================
FAIL [0.006s]: test_Case_NV_34 (test_json_tests.MyTestCase)
Invalid syntax, node separator2 modified
----------------------------------------------------------------------
Traceback (most recent call last):
  File "C:\Users\ALEJANDRA\AppData\Local\Programs\Python\Python38\lib\unittest\case.py", line 60, in testPartExecutor
    yield
  File "C:\Users\ALEJANDRA\AppData\Local\Programs\Python\Python38\lib\unittest\case.py", line 676, in run
    self._callTestMethod(testMethod)
  File "C:\Users\ALEJANDRA\AppData\Local\Programs\Python\Python38\lib\unittest\case.py", line 633, in _callTestMethod
    method()
  File "c:\users\alejandra\desktop\uni\segundo\software_devel\g89.2022.t01.fp\src\unittest\python\test_json_tests.py", line 317, in test_Case_NV_34
    test_file = self.test_json + "/test_mod_separator2.json"
  File "C:\Users\ALEJANDRA\AppData\Local\Programs\Python\Python38\lib\unittest\case.py", line 227, in __exit__
    self._raiseFailure("{} not raised".format(exc_name))
  File "C:\Users\ALEJANDRA\AppData\Local\Programs\Python\Python38\lib\unittest\case.py", line 164, in _raiseFailure
    raise self.test_case.failureException(msg)
AssertionError: VaccineManagementException not raised

======================================================================
FAIL [0.006s]: test_Case_NV_35 (test_json_tests.MyTestCase)
Invalid syntax, node 45 deleted
----------------------------------------------------------------------
Traceback (most recent call last):
  File "C:\Users\ALEJANDRA\AppData\Local\Programs\Python\Python38\lib\unittest\case.py", line 60, in testPartExecutor
    yield
  File "C:\Users\ALEJANDRA\AppData\Local\Programs\Python\Python38\lib\unittest\case.py", line 676, in run
    self._callTestMethod(testMethod)
  File "C:\Users\ALEJANDRA\AppData\Local\Programs\Python\Python38\lib\unittest\case.py", line 633, in _callTestMethod
    method()
  File "c:\users\alejandra\desktop\uni\segundo\software_devel\g89.2022.t01.fp\src\unittest\python\test_json_tests.py", line 325, in test_Case_NV_35
    test_file = self.test_json + "/test_del_node45.json"
  File "C:\Users\ALEJANDRA\AppData\Local\Programs\Python\Python38\lib\unittest\case.py", line 227, in __exit__
    self._raiseFailure("{} not raised".format(exc_name))
  File "C:\Users\ALEJANDRA\AppData\Local\Programs\Python\Python38\lib\unittest\case.py", line 164, in _raiseFailure
    raise self.test_case.failureException(msg)
AssertionError: VaccineManagementException not raised

======================================================================
FAIL [0.007s]: test_Case_NV_36 (test_json_tests.MyTestCase)
Invalid syntax, node 45 duplicated
----------------------------------------------------------------------
Traceback (most recent call last):
  File "C:\Users\ALEJANDRA\AppData\Local\Programs\Python\Python38\lib\unittest\case.py", line 60, in testPartExecutor
    yield
  File "C:\Users\ALEJANDRA\AppData\Local\Programs\Python\Python38\lib\unittest\case.py", line 676, in run
    self._callTestMethod(testMethod)
  File "C:\Users\ALEJANDRA\AppData\Local\Programs\Python\Python38\lib\unittest\case.py", line 633, in _callTestMethod
    method()
  File "c:\users\alejandra\desktop\uni\segundo\software_devel\g89.2022.t01.fp\src\unittest\python\test_json_tests.py", line 333, in test_Case_NV_36
    test_file = self.test_json +  "/test_dup_node24.json"
  File "C:\Users\ALEJANDRA\AppData\Local\Programs\Python\Python38\lib\unittest\case.py", line 227, in __exit__
    self._raiseFailure("{} not raised".format(exc_name))
  File "C:\Users\ALEJANDRA\AppData\Local\Programs\Python\Python38\lib\unittest\case.py", line 164, in _raiseFailure
    raise self.test_case.failureException(msg)
AssertionError: VaccineManagementException not raised

======================================================================
FAIL [0.006s]: test_Case_NV_37 (test_json_tests.MyTestCase)
Invalid syntax, node 45 modified
----------------------------------------------------------------------
Traceback (most recent call last):
  File "C:\Users\ALEJANDRA\AppData\Local\Programs\Python\Python38\lib\unittest\case.py", line 60, in testPartExecutor
    yield
  File "C:\Users\ALEJANDRA\AppData\Local\Programs\Python\Python38\lib\unittest\case.py", line 676, in run
    self._callTestMethod(testMethod)
  File "C:\Users\ALEJANDRA\AppData\Local\Programs\Python\Python38\lib\unittest\case.py", line 633, in _callTestMethod
    method()
  File "c:\users\alejandra\desktop\uni\segundo\software_devel\g89.2022.t01.fp\src\unittest\python\test_json_tests.py", line 341, in test_Case_NV_37
    test_file = self.test_json + "/test_mod_node24.json"
  File "C:\Users\ALEJANDRA\AppData\Local\Programs\Python\Python38\lib\unittest\case.py", line 227, in __exit__
    self._raiseFailure("{} not raised".format(exc_name))
  File "C:\Users\ALEJANDRA\AppData\Local\Programs\Python\Python38\lib\unittest\case.py", line 164, in _raiseFailure
    raise self.test_case.failureException(msg)
AssertionError: VaccineManagementException not raised

======================================================================
FAIL [0.006s]: test_Case_NV_38 (test_json_tests.MyTestCase)
Invalid syntax, node 48 deleted
----------------------------------------------------------------------
Traceback (most recent call last):
  File "C:\Users\ALEJANDRA\AppData\Local\Programs\Python\Python38\lib\unittest\case.py", line 60, in testPartExecutor
    yield
  File "C:\Users\ALEJANDRA\AppData\Local\Programs\Python\Python38\lib\unittest\case.py", line 676, in run
    self._callTestMethod(testMethod)
  File "C:\Users\ALEJANDRA\AppData\Local\Programs\Python\Python38\lib\unittest\case.py", line 633, in _callTestMethod
    method()
  File "c:\users\alejandra\desktop\uni\segundo\software_devel\g89.2022.t01.fp\src\unittest\python\test_json_tests.py", line 349, in test_Case_NV_38
    test_file = self.test_json + "/test_del_node45.json"
  File "C:\Users\ALEJANDRA\AppData\Local\Programs\Python\Python38\lib\unittest\case.py", line 227, in __exit__
    self._raiseFailure("{} not raised".format(exc_name))
  File "C:\Users\ALEJANDRA\AppData\Local\Programs\Python\Python38\lib\unittest\case.py", line 164, in _raiseFailure
    raise self.test_case.failureException(msg)
AssertionError: VaccineManagementException not raised

======================================================================
FAIL [0.005s]: test_Case_NV_39 (test_json_tests.MyTestCase)
Invalid syntax, node 48 duplicated
----------------------------------------------------------------------
Traceback (most recent call last):
  File "C:\Users\ALEJANDRA\AppData\Local\Programs\Python\Python38\lib\unittest\case.py", line 60, in testPartExecutor
    yield
  File "C:\Users\ALEJANDRA\AppData\Local\Programs\Python\Python38\lib\unittest\case.py", line 676, in run
    self._callTestMethod(testMethod)
  File "C:\Users\ALEJANDRA\AppData\Local\Programs\Python\Python38\lib\unittest\case.py", line 633, in _callTestMethod
    method()
  File "c:\users\alejandra\desktop\uni\segundo\software_devel\g89.2022.t01.fp\src\unittest\python\test_json_tests.py", line 357, in test_Case_NV_39
    test_file = self.test_json + "/test_dup_node28.json"
  File "C:\Users\ALEJANDRA\AppData\Local\Programs\Python\Python38\lib\unittest\case.py", line 227, in __exit__
    self._raiseFailure("{} not raised".format(exc_name))
  File "C:\Users\ALEJANDRA\AppData\Local\Programs\Python\Python38\lib\unittest\case.py", line 164, in _raiseFailure
    raise self.test_case.failureException(msg)
AssertionError: VaccineManagementException not raised

======================================================================
FAIL [0.006s]: test_Case_NV_40 (test_json_tests.MyTestCase)
Invalid syntax, node 48 modified
----------------------------------------------------------------------
Traceback (most recent call last):
  File "C:\Users\ALEJANDRA\AppData\Local\Programs\Python\Python38\lib\unittest\case.py", line 60, in testPartExecutor
    yield
  File "C:\Users\ALEJANDRA\AppData\Local\Programs\Python\Python38\lib\unittest\case.py", line 676, in run
    self._callTestMethod(testMethod)
  File "C:\Users\ALEJANDRA\AppData\Local\Programs\Python\Python38\lib\unittest\case.py", line 633, in _callTestMethod
    method()
  File "c:\users\alejandra\desktop\uni\segundo\software_devel\g89.2022.t01.fp\src\unittest\python\test_json_tests.py", line 365, in test_Case_NV_40
    test_file = self.test_json + "/test_mod_node28.json"
  File "C:\Users\ALEJANDRA\AppData\Local\Programs\Python\Python38\lib\unittest\case.py", line 227, in __exit__
    self._raiseFailure("{} not raised".format(exc_name))
  File "C:\Users\ALEJANDRA\AppData\Local\Programs\Python\Python38\lib\unittest\case.py", line 164, in _raiseFailure
    raise self.test_case.failureException(msg)
AssertionError: VaccineManagementException not raised

======================================================================
FAIL [0.006s]: test_Case_NV_41 (test_json_tests.MyTestCase)
Invalid syntax, node 51 deleted
----------------------------------------------------------------------
Traceback (most recent call last):
  File "C:\Users\ALEJANDRA\AppData\Local\Programs\Python\Python38\lib\unittest\case.py", line 60, in testPartExecutor
    yield
  File "C:\Users\ALEJANDRA\AppData\Local\Programs\Python\Python38\lib\unittest\case.py", line 676, in run
    self._callTestMethod(testMethod)
  File "C:\Users\ALEJANDRA\AppData\Local\Programs\Python\Python38\lib\unittest\case.py", line 633, in _callTestMethod
    method()
  File "c:\users\alejandra\desktop\uni\segundo\software_devel\g89.2022.t01.fp\src\unittest\python\test_json_tests.py", line 373, in test_Case_NV_41
    test_file = self.test_json + "/test_del_node51.json"
  File "C:\Users\ALEJANDRA\AppData\Local\Programs\Python\Python38\lib\unittest\case.py", line 227, in __exit__
    self._raiseFailure("{} not raised".format(exc_name))
  File "C:\Users\ALEJANDRA\AppData\Local\Programs\Python\Python38\lib\unittest\case.py", line 164, in _raiseFailure
    raise self.test_case.failureException(msg)
AssertionError: VaccineManagementException not raised

======================================================================
FAIL [0.006s]: test_Case_NV_42 (test_json_tests.MyTestCase)
Invalid syntax, node 51 duplicated
----------------------------------------------------------------------
Traceback (most recent call last):
  File "C:\Users\ALEJANDRA\AppData\Local\Programs\Python\Python38\lib\unittest\case.py", line 60, in testPartExecutor
    yield
  File "C:\Users\ALEJANDRA\AppData\Local\Programs\Python\Python38\lib\unittest\case.py", line 676, in run
    self._callTestMethod(testMethod)
  File "C:\Users\ALEJANDRA\AppData\Local\Programs\Python\Python38\lib\unittest\case.py", line 633, in _callTestMethod
    method()
  File "c:\users\alejandra\desktop\uni\segundo\software_devel\g89.2022.t01.fp\src\unittest\python\test_json_tests.py", line 381, in test_Case_NV_42
    test_file = self.test_json + "/test_dup_node31.json"
  File "C:\Users\ALEJANDRA\AppData\Local\Programs\Python\Python38\lib\unittest\case.py", line 227, in __exit__
    self._raiseFailure("{} not raised".format(exc_name))
  File "C:\Users\ALEJANDRA\AppData\Local\Programs\Python\Python38\lib\unittest\case.py", line 164, in _raiseFailure
    raise self.test_case.failureException(msg)
AssertionError: VaccineManagementException not raised

======================================================================
FAIL [0.006s]: test_Case_NV_43 (test_json_tests.MyTestCase)
Invalid syntax, node 51 modified
----------------------------------------------------------------------
Traceback (most recent call last):
  File "C:\Users\ALEJANDRA\AppData\Local\Programs\Python\Python38\lib\unittest\case.py", line 60, in testPartExecutor
    yield
  File "C:\Users\ALEJANDRA\AppData\Local\Programs\Python\Python38\lib\unittest\case.py", line 676, in run
    self._callTestMethod(testMethod)
  File "C:\Users\ALEJANDRA\AppData\Local\Programs\Python\Python38\lib\unittest\case.py", line 633, in _callTestMethod
    method()
  File "c:\users\alejandra\desktop\uni\segundo\software_devel\g89.2022.t01.fp\src\unittest\python\test_json_tests.py", line 389, in test_Case_NV_43
    test_file = self.test_json + "/test_mod_node31.json"
  File "C:\Users\ALEJANDRA\AppData\Local\Programs\Python\Python38\lib\unittest\case.py", line 227, in __exit__
    self._raiseFailure("{} not raised".format(exc_name))
  File "C:\Users\ALEJANDRA\AppData\Local\Programs\Python\Python38\lib\unittest\case.py", line 164, in _raiseFailure
    raise self.test_case.failureException(msg)
AssertionError: VaccineManagementException not raised

======================================================================
FAIL [0.007s]: test_Case_NV_44 (test_json_tests.MyTestCase)
Invalid syntax, node 54 deleted
----------------------------------------------------------------------
Traceback (most recent call last):
  File "C:\Users\ALEJANDRA\AppData\Local\Programs\Python\Python38\lib\unittest\case.py", line 60, in testPartExecutor
    yield
  File "C:\Users\ALEJANDRA\AppData\Local\Programs\Python\Python38\lib\unittest\case.py", line 676, in run
    self._callTestMethod(testMethod)
  File "C:\Users\ALEJANDRA\AppData\Local\Programs\Python\Python38\lib\unittest\case.py", line 633, in _callTestMethod
    method()
  File "c:\users\alejandra\desktop\uni\segundo\software_devel\g89.2022.t01.fp\src\unittest\python\test_json_tests.py", line 397, in test_Case_NV_44
    test_file = self.test_json + "/test_del_node54.json"
  File "C:\Users\ALEJANDRA\AppData\Local\Programs\Python\Python38\lib\unittest\case.py", line 227, in __exit__
    self._raiseFailure("{} not raised".format(exc_name))
  File "C:\Users\ALEJANDRA\AppData\Local\Programs\Python\Python38\lib\unittest\case.py", line 164, in _raiseFailure
    raise self.test_case.failureException(msg)
AssertionError: VaccineManagementException not raised

======================================================================
FAIL [0.006s]: test_Case_NV_45 (test_json_tests.MyTestCase)
Invalid syntax, node 54 duplicated
----------------------------------------------------------------------
Traceback (most recent call last):
  File "C:\Users\ALEJANDRA\AppData\Local\Programs\Python\Python38\lib\unittest\case.py", line 60, in testPartExecutor
    yield
  File "C:\Users\ALEJANDRA\AppData\Local\Programs\Python\Python38\lib\unittest\case.py", line 676, in run
    self._callTestMethod(testMethod)
  File "C:\Users\ALEJANDRA\AppData\Local\Programs\Python\Python38\lib\unittest\case.py", line 633, in _callTestMethod
    method()
  File "c:\users\alejandra\desktop\uni\segundo\software_devel\g89.2022.t01.fp\src\unittest\python\test_json_tests.py", line 405, in test_Case_NV_45
    test_file = self.test_json + "/test_dup_node35.json"
  File "C:\Users\ALEJANDRA\AppData\Local\Programs\Python\Python38\lib\unittest\case.py", line 227, in __exit__
    self._raiseFailure("{} not raised".format(exc_name))
  File "C:\Users\ALEJANDRA\AppData\Local\Programs\Python\Python38\lib\unittest\case.py", line 164, in _raiseFailure
    raise self.test_case.failureException(msg)
AssertionError: VaccineManagementException not raised

======================================================================
FAIL [0.005s]: test_Case_NV_46 (test_json_tests.MyTestCase)
Invalid syntax, node 54 modified
----------------------------------------------------------------------
Traceback (most recent call last):
  File "C:\Users\ALEJANDRA\AppData\Local\Programs\Python\Python38\lib\unittest\case.py", line 60, in testPartExecutor
    yield
  File "C:\Users\ALEJANDRA\AppData\Local\Programs\Python\Python38\lib\unittest\case.py", line 676, in run
    self._callTestMethod(testMethod)
  File "C:\Users\ALEJANDRA\AppData\Local\Programs\Python\Python38\lib\unittest\case.py", line 633, in _callTestMethod
    method()
  File "c:\users\alejandra\desktop\uni\segundo\software_devel\g89.2022.t01.fp\src\unittest\python\test_json_tests.py", line 413, in test_Case_NV_46
    test_file = self.test_json + "/test_mod_node35.json"
  File "C:\Users\ALEJANDRA\AppData\Local\Programs\Python\Python38\lib\unittest\case.py", line 227, in __exit__
    self._raiseFailure("{} not raised".format(exc_name))
  File "C:\Users\ALEJANDRA\AppData\Local\Programs\Python\Python38\lib\unittest\case.py", line 164, in _raiseFailure
    raise self.test_case.failureException(msg)
AssertionError: VaccineManagementException not raised

======================================================================
FAIL [0.008s]: test_Case_NV_47 (test_json_tests.MyTestCase)
Invalid syntax, node 57 deleted
----------------------------------------------------------------------
Traceback (most recent call last):
  File "C:\Users\ALEJANDRA\AppData\Local\Programs\Python\Python38\lib\unittest\case.py", line 60, in testPartExecutor
    yield
  File "C:\Users\ALEJANDRA\AppData\Local\Programs\Python\Python38\lib\unittest\case.py", line 676, in run
    self._callTestMethod(testMethod)
  File "C:\Users\ALEJANDRA\AppData\Local\Programs\Python\Python38\lib\unittest\case.py", line 633, in _callTestMethod
    method()
  File "c:\users\alejandra\desktop\uni\segundo\software_devel\g89.2022.t01.fp\src\unittest\python\test_json_tests.py", line 421, in test_Case_NV_47
    test_file = self.test_json + "/test_del_node57.json"
  File "C:\Users\ALEJANDRA\AppData\Local\Programs\Python\Python38\lib\unittest\case.py", line 227, in __exit__
    self._raiseFailure("{} not raised".format(exc_name))
  File "C:\Users\ALEJANDRA\AppData\Local\Programs\Python\Python38\lib\unittest\case.py", line 164, in _raiseFailure
    raise self.test_case.failureException(msg)
AssertionError: VaccineManagementException not raised

======================================================================
FAIL [0.006s]: test_Case_NV_48 (test_json_tests.MyTestCase)
Invalid syntax, node 57 duplicated
----------------------------------------------------------------------
Traceback (most recent call last):
  File "C:\Users\ALEJANDRA\AppData\Local\Programs\Python\Python38\lib\unittest\case.py", line 60, in testPartExecutor
    yield
  File "C:\Users\ALEJANDRA\AppData\Local\Programs\Python\Python38\lib\unittest\case.py", line 676, in run
    self._callTestMethod(testMethod)
  File "C:\Users\ALEJANDRA\AppData\Local\Programs\Python\Python38\lib\unittest\case.py", line 633, in _callTestMethod
    method()
  File "c:\users\alejandra\desktop\uni\segundo\software_devel\g89.2022.t01.fp\src\unittest\python\test_json_tests.py", line 429, in test_Case_NV_48
    test_file = self.test_json + "/test_dup_node38.json"
  File "C:\Users\ALEJANDRA\AppData\Local\Programs\Python\Python38\lib\unittest\case.py", line 227, in __exit__
    self._raiseFailure("{} not raised".format(exc_name))
  File "C:\Users\ALEJANDRA\AppData\Local\Programs\Python\Python38\lib\unittest\case.py", line 164, in _raiseFailure
    raise self.test_case.failureException(msg)
AssertionError: VaccineManagementException not raised

======================================================================
FAIL [0.006s]: test_Case_NV_49 (test_json_tests.MyTestCase)
Invalid syntax, node 57 modified
----------------------------------------------------------------------
Traceback (most recent call last):
  File "C:\Users\ALEJANDRA\AppData\Local\Programs\Python\Python38\lib\unittest\case.py", line 60, in testPartExecutor
    yield
  File "C:\Users\ALEJANDRA\AppData\Local\Programs\Python\Python38\lib\unittest\case.py", line 676, in run
    self._callTestMethod(testMethod)
  File "C:\Users\ALEJANDRA\AppData\Local\Programs\Python\Python38\lib\unittest\case.py", line 633, in _callTestMethod
    method()
  File "c:\users\alejandra\desktop\uni\segundo\software_devel\g89.2022.t01.fp\src\unittest\python\test_json_tests.py", line 437, in test_Case_NV_49
    test_file = self.test_json + "/test_mod_node38.json"
  File "C:\Users\ALEJANDRA\AppData\Local\Programs\Python\Python38\lib\unittest\case.py", line 227, in __exit__
    self._raiseFailure("{} not raised".format(exc_name))
  File "C:\Users\ALEJANDRA\AppData\Local\Programs\Python\Python38\lib\unittest\case.py", line 164, in _raiseFailure
    raise self.test_case.failureException(msg)
AssertionError: VaccineManagementException not raised

======================================================================
FAIL [0.007s]: test_Case_NV_50 (test_json_tests.MyTestCase)
Invalid syntax, node 60 deleted
----------------------------------------------------------------------
Traceback (most recent call last):
  File "C:\Users\ALEJANDRA\AppData\Local\Programs\Python\Python38\lib\unittest\case.py", line 60, in testPartExecutor
    yield
  File "C:\Users\ALEJANDRA\AppData\Local\Programs\Python\Python38\lib\unittest\case.py", line 676, in run
    self._callTestMethod(testMethod)
  File "C:\Users\ALEJANDRA\AppData\Local\Programs\Python\Python38\lib\unittest\case.py", line 633, in _callTestMethod
    method()
  File "c:\users\alejandra\desktop\uni\segundo\software_devel\g89.2022.t01.fp\src\unittest\python\test_json_tests.py", line 445, in test_Case_NV_50
    test_file = self.test_json + "/test_del_node60.json"
  File "C:\Users\ALEJANDRA\AppData\Local\Programs\Python\Python38\lib\unittest\case.py", line 227, in __exit__
    self._raiseFailure("{} not raised".format(exc_name))
  File "C:\Users\ALEJANDRA\AppData\Local\Programs\Python\Python38\lib\unittest\case.py", line 164, in _raiseFailure
    raise self.test_case.failureException(msg)
AssertionError: VaccineManagementException not raised

======================================================================
FAIL [0.007s]: test_Case_NV_51 (test_json_tests.MyTestCase)
Invalid syntax, node 60 duplicated
----------------------------------------------------------------------
Traceback (most recent call last):
  File "C:\Users\ALEJANDRA\AppData\Local\Programs\Python\Python38\lib\unittest\case.py", line 60, in testPartExecutor
    yield
  File "C:\Users\ALEJANDRA\AppData\Local\Programs\Python\Python38\lib\unittest\case.py", line 676, in run
    self._callTestMethod(testMethod)
  File "C:\Users\ALEJANDRA\AppData\Local\Programs\Python\Python38\lib\unittest\case.py", line 633, in _callTestMethod
    method()
  File "c:\users\alejandra\desktop\uni\segundo\software_devel\g89.2022.t01.fp\src\unittest\python\test_json_tests.py", line 453, in test_Case_NV_51
    test_file = self.test_json + "/test_dup_node42.json"
  File "C:\Users\ALEJANDRA\AppData\Local\Programs\Python\Python38\lib\unittest\case.py", line 227, in __exit__
    self._raiseFailure("{} not raised".format(exc_name))
  File "C:\Users\ALEJANDRA\AppData\Local\Programs\Python\Python38\lib\unittest\case.py", line 164, in _raiseFailure
    raise self.test_case.failureException(msg)
AssertionError: VaccineManagementException not raised

======================================================================
FAIL [0.006s]: test_Case_NV_52 (test_json_tests.MyTestCase)
Invalid syntax, node 60 modified
----------------------------------------------------------------------
Traceback (most recent call last):
  File "C:\Users\ALEJANDRA\AppData\Local\Programs\Python\Python38\lib\unittest\case.py", line 60, in testPartExecutor
    yield
  File "C:\Users\ALEJANDRA\AppData\Local\Programs\Python\Python38\lib\unittest\case.py", line 676, in run
    self._callTestMethod(testMethod)
  File "C:\Users\ALEJANDRA\AppData\Local\Programs\Python\Python38\lib\unittest\case.py", line 633, in _callTestMethod
    method()
  File "c:\users\alejandra\desktop\uni\segundo\software_devel\g89.2022.t01.fp\src\unittest\python\test_json_tests.py", line 461, in test_Case_NV_52
    test_file = self.test_json + "/test_mod_node42.json"
  File "C:\Users\ALEJANDRA\AppData\Local\Programs\Python\Python38\lib\unittest\case.py", line 227, in __exit__
    self._raiseFailure("{} not raised".format(exc_name))
  File "C:\Users\ALEJANDRA\AppData\Local\Programs\Python\Python38\lib\unittest\case.py", line 164, in _raiseFailure
    raise self.test_case.failureException(msg)
AssertionError: VaccineManagementException not raised

----------------------------------------------------------------------
Ran 88 tests in 1.136s

FAILED (failures=51, errors=30, skipped=1)

Generating XML reports...
